Workbook
Name AL: OLD!$A$3:$A$30
Name Month: 'Quad-Tech'!$C$2:$C$13
Name PRO023_: OLD!#REF!
Name 工程編號: OLD!$A$2:$A$30

Sheet 2023 Time Sheet
A1: TIMESHEET（工作時間記錄表）
P2: /2023
A3: NAME（姓名）： | M3: MONTH（月份）： | N3: Mar
A5: POSITION（職位）： | M5: DEPT.（部門）：
A7: 日期 | D7: 星期 | E7: TIME（時間）－只需填寫工程合約編號（例：2380EM20M） | N7: (加班時段) | O7: (查核簽名) | P7: (備註)
B8: DATE | D8: DAY | E8: 09 - 10 | F8: 10 - 11 | G8: 11 - 12 | H8: 12 - 13:30 | J8: 13:30 - 15 | K8: 15 - 16 | L8: 16 - 17 | M8: 17 - 18 | N8: OT (O/N, PH) | O8: CHECKED BY | P8: REMARKS | Q8: NPL | S8: PH | U8: SL | W8: AL | Y8: CL | AA8: OFF | AC8: Admin | AE8: 2107EM20M | AG8: 2656EM20M | AI8: 3083EM20M | AK8: 2435EM21M | AM8: 1497EM22M | AO8: 1611EM22M | AQ8: 1865EM22M | AS8: 1735EM22W | AU8: 元朗宏業西街 | AW8: Kai Tak 1B2 | AY8: Tsat Sing Kong | BA8: 焚化爐（MVAC & ELV） | BC8: General Tendering | BE8: EMSD Tender | BG8: Kai Tak 1B3 | BI8: GDS KC1 | BK8: GDS KC2 | CO8: L | CQ8: M
A9: =IF(N3="Jan",'Quad-Tech'!A2,IF(N3="Feb",'Quad-Tech'!A33,IF(N3="Mar",'Quad-Tech'!A61,IF(N3="Apr",'Quad-Tech'!A92,IF(N3="May",'Quad-Tech'!A122,IF(N3="Jun",'Quad-Tech'!A153,IF(N3="Jul",'Quad-Tech'!A183,IF(N3="Aug",'Quad-Tech'!A214,IF(N3="Sep",'Quad-Tech'!A245,IF(N3="Oct",'Quad-Tech'!A275,IF(N3="Nov",'Quad-Tech'!A306,IF(N3="Dec",'Quad-Tech'!A336)))))))))))) -> 44986 | D9: =VLOOKUP(A9,'Quad-Tech'!A2:B366,2,FALSE) -> Wed | E9: 2656EM20M | J9: EMSD Tender | Q9: =IF($E9=Q$8,1,0) -> 0 | R9: =IF($J9=Q$8,1,0) -> 0 | S9: =IF($E9=S$8,1,0) -> 0 | T9: =IF($J9=S$8,1,0) -> 0 | U9: =IF($E9=U$8,1,0) -> 0 | V9: =IF($J9=U$8,1,0) -> 0 | W9: =IF($E9=W$8,1,0) -> 0 | X9: =IF($J9=W$8,1,0) -> 0 | Y9: =IF($E9=Y$8,1,0) -> 0 | Z9: =IF($J9=Y$8,1,0) -> 0 | AA9: =IF($E9=AA$8,1,0) -> 0 | AB9: =IF($J9=AA$8,1,0) -> 0 | AC9: =IF($E9=AC$8,1,0) -> 0 | AD9: =IF($J9=AC$8,1,0) -> 0 | AE9: =IF($E9=AE$8,1,0) -> 0 | AF9: =IF($J9=AE$8,1,0) -> 0 | AG9: =IF($E9=AG$8,1,0) -> 1 | AH9: =IF($J9=AG$8,1,0) -> 0 | AI9: =IF($E9=AI$8,1,0) -> 0 | AJ9: =IF($J9=AI$8,1,0) -> 0 | AK9: =IF($E9=AK$8,1,0) -> 0 | AL9: =IF($J9=AK$8,1,0) -> 0 | AM9: =IF($E9=AM$8,1,0) -> 0 | AN9: =IF($J9=AM$8,1,0) -> 0 | AO9: =IF($E9=AO$8,1,0) -> 0 | AP9: =IF($J9=AO$8,1,0) -> 0 | AQ9: =IF($E9=AQ$8,1,0) -> 0 | AR9: =IF($J9=AQ$8,1,0) -> 0 | AS9: =IF($E9=AS$8,1,0) -> 0 | AT9: =IF($J9=AS$8,1,0) -> 0 | AU9: =IF($E9=AU$8,1,0) -> 0 | AV9: =IF($J9=AU$8,1,0) -> 0 | AW9: =IF($E9=AW$8,1,0) -> 0 | AX9: =IF($J9=AW$8,1,0) -> 0 | AY9: =IF($E9=AY$8,1,0) -> 0 | AZ9: =IF($J9=AY$8,1,0) -> 0 | BA9: =IF($E9=BA$8,1,0) -> 0 | BB9: =IF($J9=BA$8,1,0) -> 0 | BC9: =IF($E9=BC$8,1,0) -> 0 | BD9: =IF($J9=BC$8,1,0) -> 0 | BE9: =IF($E9=BE$8,1,0) -> 0 | BF9: =IF($J9=BE$8,1,0) -> 1 | BG9: =IF($E9=BG$8,1,0) -> 0 | BH9: =IF($J9=BG$8,1,0) -> 0 | BI9: =IF($E9=BI$8,1,0) -> 0 | BJ9: =IF($J9=BI$8,1,0) -> 0 | BK9: =IF($E9=BK$8,1,0) -> 0 | BL9: =IF($J9=BK$8,1,0) -> 0 | BM9: =IF($E9=BM$8,1,0) -> 0 | BN9: =IF($J9=BM$8,1,0) -> 0 | BO9: =IF($E9=BO$8,1,0) -> 0 | BP9: =IF($J9=BO$8,1,0) -> 0 | BQ9: =IF($E9=BQ$8,1,0) -> 0 | BR9: =IF($J9=BQ$8,1,0) -> 0 | BS9: =IF($E9=BS$8,1,0) -> 0 | BT9: =IF($J9=BS$8,1,0) -> 0 | BU9: =IF($E9=BU$8,1,0) -> 0 | BV9: =IF($J9=BU$8,1,0) -> 0 | BW9: =IF($E9=BW$8,1,0) -> 0 | BX9: =IF($J9=BW$8,1,0) -> 0 | BY9: =IF($E9=BY$8,1,0) -> 0 | BZ9: =IF($J9=BY$8,1,0) -> 0 | CA9: =IF($E9=CA$8,1,0) -> 0 | CB9: =IF($J9=CA$8,1,0) -> 0 | CC9: =IF($E9=CC$8,1,0) -> 0 | CD9: =IF($J9=CC$8,1,0) -> 0 | CE9: =IF($E9=CE$8,1,0) -> 0 | CF9: =IF($J9=CE$8,1,0) -> 0 | CG9: =IF($E9=CG$8,1,0) -> 0 | CH9: =IF($J9=CG$8,1,0) -> 0 | CI9: =IF($E9=CI$8,1,0) -> 0 | CJ9: =IF($J9=CI$8,1,0) -> 0 | CK9: =IF($E9=CK$8,1,0) -> 0 | CL9: =IF($J9=CK$8,1,0) -> 0 | CM9: =IF($E9=CM$8,1,0) -> 0 | CN9: =IF($J9=CM$8,1,0) -> 0 | CO9: =IF($E9=CO$8,1,0) -> 0 | CP9: =IF($J9=CO$8,1,0) -> 0 | CQ9: =IF($E9=CQ$8,1,0) -> 0 | CR9: =IF($J9=CQ$8,1,0) -> 0 | CS9: =SUM(Q9:CR9) -> 2 | CT9: =IFERROR((VLOOKUP(A9,'Quad-Tech'!$F$1:$G$17,2,FALSE)),0) -> 0
A10: =A9+1 -> 44987 | D10: =VLOOKUP(A10,'Quad-Tech'!A3:B367,2,FALSE) -> Thu | E10: 1735EM22W | J10: 1735EM22W | Q10: =IF($E10=Q$8,1,0) -> 0 | R10: =IF($J10=Q$8,1,0) -> 0 | S10: =IF($E10=S$8,1,0) -> 0 | T10: =IF($J10=S$8,1,0) -> 0 | U10: =IF($E10=U$8,1,0) -> 0 | V10: =IF($J10=U$8,1,0) -> 0 | W10: =IF($E10=W$8,1,0) -> 0 | X10: =IF($J10=W$8,1,0) -> 0 | Y10: =IF($E10=Y$8,1,0) -> 0 | Z10: =IF($J10=Y$8,1,0) -> 0 | AA10: =IF($E10=AA$8,1,0) -> 0 | AB10: =IF($J10=AA$8,1,0) -> 0 | AC10: =IF($E10=AC$8,1,0) -> 0 | AD10: =IF($J10=AC$8,1,0) -> 0 | AE10: =IF($E10=AE$8,1,0) -> 0 | AF10: =IF($J10=AE$8,1,0) -> 0 | AG10: =IF($E10=AG$8,1,0) -> 0 | AH10: =IF($J10=AG$8,1,0) -> 0 | AI10: =IF($E10=AI$8,1,0) -> 0 | AJ10: =IF($J10=AI$8,1,0) -> 0 | AK10: =IF($E10=AK$8,1,0) -> 0 | AL10: =IF($J10=AK$8,1,0) -> 0 | AM10: =IF($E10=AM$8,1,0) -> 0 | AN10: =IF($J10=AM$8,1,0) -> 0 | AO10: =IF($E10=AO$8,1,0) -> 0 | AP10: =IF($J10=AO$8,1,0) -> 0 | AQ10: =IF($E10=AQ$8,1,0) -> 0 | AR10: =IF($J10=AQ$8,1,0) -> 0 | AS10: =IF($E10=AS$8,1,0) -> 1 | AT10: =IF($J10=AS$8,1,0) -> 1 | AU10: =IF($E10=AU$8,1,0) -> 0 | AV10: =IF($J10=AU$8,1,0) -> 0 | AW10: =IF($E10=AW$8,1,0) -> 0 | AX10: =IF($J10=AW$8,1,0) -> 0 | AY10: =IF($E10=AY$8,1,0) -> 0 | AZ10: =IF($J10=AY$8,1,0) -> 0 | BA10: =IF($E10=BA$8,1,0) -> 0 | BB10: =IF($J10=BA$8,1,0) -> 0 | BC10: =IF($E10=BC$8,1,0) -> 0 | BD10: =IF($J10=BC$8,1,0) -> 0 | BE10: =IF($E10=BE$8,1,0) -> 0 | BF10: =IF($J10=BE$8,1,0) -> 0 | BG10: =IF($E10=BG$8,1,0) -> 0 | BH10: =IF($J10=BG$8,1,0) -> 0 | BI10: =IF($E10=BI$8,1,0) -> 0 | BJ10: =IF($J10=BI$8,1,0) -> 0 | BK10: =IF($E10=BK$8,1,0) -> 0 | BL10: =IF($J10=BK$8,1,0) -> 0 | BM10: =IF($E10=BM$8,1,0) -> 0 | BN10: =IF($J10=BM$8,1,0) -> 0 | BO10: =IF($E10=BO$8,1,0) -> 0 | BP10: =IF($J10=BO$8,1,0) -> 0 | BQ10: =IF($E10=BQ$8,1,0) -> 0 | BR10: =IF($J10=BQ$8,1,0) -> 0 | BS10: =IF($E10=BS$8,1,0) -> 0 | BT10: =IF($J10=BS$8,1,0) -> 0 | BU10: =IF($E10=BU$8,1,0) -> 0 | BV10: =IF($J10=BU$8,1,0) -> 0 | BW10: =IF($E10=BW$8,1,0) -> 0 | BX10: =IF($J10=BW$8,1,0) -> 0 | BY10: =IF($E10=BY$8,1,0) -> 0 | BZ10: =IF($J10=BY$8,1,0) -> 0 | CA10: =IF($E10=CA$8,1,0) -> 0 | CB10: =IF($J10=CA$8,1,0) -> 0 | CC10: =IF($E10=CC$8,1,0) -> 0 | CD10: =IF($J10=CC$8,1,0) -> 0 | CE10: =IF($E10=CE$8,1,0) -> 0 | CF10: =IF($J10=CE$8,1,0) -> 0 | CG10: =IF($E10=CG$8,1,0) -> 0 | CH10: =IF($J10=CG$8,1,0) -> 0 | CI10: =IF($E10=CI$8,1,0) -> 0 | CJ10: =IF($J10=CI$8,1,0) -> 0 | CK10: =IF($E10=CK$8,1,0) -> 0 | CL10: =IF($J10=CK$8,1,0) -> 0 | CM10: =IF($E10=CM$8,1,0) -> 0 | CN10: =IF($J10=CM$8,1,0) -> 0 | CO10: =IF($E10=CO$8,1,0) -> 0 | CP10: =IF($J10=CO$8,1,0) -> 0 | CQ10: =IF($E10=CQ$8,1,0) -> 0 | CR10: =IF($J10=CQ$8,1,0) -> 0 | CS10: =(SUM(Q10:CL10))+(SUM(Q10:CR10)) -> 4 | CT10: =IFERROR((VLOOKUP(A10,'Quad-Tech'!$F$1:$G$17,2,FALSE)),0) -> 0
A11: =A10+1 -> 44988 | D11: =VLOOKUP(A11,'Quad-Tech'!A4:B368,2,FALSE) -> Fri | E11: 1735EM22W | J11: 1735EM22W | Q11: =IF($E11=Q$8,1,0) -> 0 | R11: =IF($J11=Q$8,1,0) -> 0 | S11: =IF($E11=S$8,1,0) -> 0 | T11: =IF($J11=S$8,1,0) -> 0 | U11: =IF($E11=U$8,1,0) -> 0 | V11: =IF($J11=U$8,1,0) -> 0 | W11: =IF($E11=W$8,1,0) -> 0 | X11: =IF($J11=W$8,1,0) -> 0 | Y11: =IF($E11=Y$8,1,0) -> 0 | Z11: =IF($J11=Y$8,1,0) -> 0 | AA11: =IF($E11=AA$8,1,0) -> 0 | AB11: =IF($J11=AA$8,1,0) -> 0 | AC11: =IF($E11=AC$8,1,0) -> 0 | AD11: =IF($J11=AC$8,1,0) -> 0 | AE11: =IF($E11=AE$8,1,0) -> 0 | AF11: =IF($J11=AE$8,1,0) -> 0 | AG11: =IF($E11=AG$8,1,0) -> 0 | AH11: =IF($J11=AG$8,1,0) -> 0 | AI11: =IF($E11=AI$8,1,0) -> 0 | AJ11: =IF($J11=AI$8,1,0) -> 0 | AK11: =IF($E11=AK$8,1,0) -> 0 | AL11: =IF($J11=AK$8,1,0) -> 0 | AM11: =IF($E11=AM$8,1,0) -> 0 | AN11: =IF($J11=AM$8,1,0) -> 0 | AO11: =IF($E11=AO$8,1,0) -> 0 | AP11: =IF($J11=AO$8,1,0) -> 0 | AQ11: =IF($E11=AQ$8,1,0) -> 0 | AR11: =IF($J11=AQ$8,1,0) -> 0 | AS11: =IF($E11=AS$8,1,0) -> 1 | AT11: =IF($J11=AS$8,1,0) -> 1 | AU11: =IF($E11=AU$8,1,0) -> 0 | AV11: =IF($J11=AU$8,1,0) -> 0 | AW11: =IF($E11=AW$8,1,0) -> 0 | AX11: =IF($J11=AW$8,1,0) -> 0 | AY11: =IF($E11=AY$8,1,0) -> 0 | AZ11: =IF($J11=AY$8,1,0) -> 0 | BA11: =IF($E11=BA$8,1,0) -> 0 | BB11: =IF($J11=BA$8,1,0) -> 0 | BC11: =IF($E11=BC$8,1,0) -> 0 | BD11: =IF($J11=BC$8,1,0) -> 0 | BE11: =IF($E11=BE$8,1,0) -> 0 | BF11: =IF($J11=BE$8,1,0) -> 0 | BG11: =IF($E11=BG$8,1,0) -> 0 | BH11: =IF($J11=BG$8,1,0) -> 0 | BI11: =IF($E11=BI$8,1,0) -> 0 | BJ11: =IF($J11=BI$8,1,0) -> 0 | BK11: =IF($E11=BK$8,1,0) -> 0 | BL11: =IF($J11=BK$8,1,0) -> 0 | BM11: =IF($E11=BM$8,1,0) -> 0 | BN11: =IF($J11=BM$8,1,0) -> 0 | BO11: =IF($E11=BO$8,1,0) -> 0 | BP11: =IF($J11=BO$8,1,0) -> 0 | BQ11: =IF($E11=BQ$8,1,0) -> 0 | BR11: =IF($J11=BQ$8,1,0) -> 0 | BS11: =IF($E11=BS$8,1,0) -> 0 | BT11: =IF($J11=BS$8,1,0) -> 0 | BU11: =IF($E11=BU$8,1,0) -> 0 | BV11: =IF($J11=BU$8,1,0) -> 0 | BW11: =IF($E11=BW$8,1,0) -> 0 | BX11: =IF($J11=BW$8,1,0) -> 0 | BY11: =IF($E11=BY$8,1,0) -> 0 | BZ11: =IF($J11=BY$8,1,0) -> 0 | CA11: =IF($E11=CA$8,1,0) -> 0 | CB11: =IF($J11=CA$8,1,0) -> 0 | CC11: =IF($E11=CC$8,1,0) -> 0 | CD11: =IF($J11=CC$8,1,0) -> 0 | CE11: =IF($E11=CE$8,1,0) -> 0 | CF11: =IF($J11=CE$8,1,0) -> 0 | CG11: =IF($E11=CG$8,1,0) -> 0 | CH11: =IF($J11=CG$8,1,0) -> 0 | CI11: =IF($E11=CI$8,1,0) -> 0 | CJ11: =IF($J11=CI$8,1,0) -> 0 | CK11: =IF($E11=CK$8,1,0) -> 0 | CL11: =IF($J11=CK$8,1,0) -> 0 | CM11: =IF($E11=CM$8,1,0) -> 0 | CN11: =IF($J11=CM$8,1,0) -> 0 | CO11: =IF($E11=CO$8,1,0) -> 0 | CP11: =IF($J11=CO$8,1,0) -> 0 | CQ11: =IF($E11=CQ$8,1,0) -> 0 | CR11: =IF($J11=CQ$8,1,0) -> 0 | CS11: =(SUM(Q11:CL11))+(SUM(Q11:CR11)) -> 4 | CT11: =IFERROR((VLOOKUP(A11,'Quad-Tech'!$F$1:$G$17,2,FALSE)),0) -> 0
A12: =A11+1 -> 44989 | D12: =VLOOKUP(A12,'Quad-Tech'!A5:B369,2,FALSE) -> Sat | E12: 2656EM20M | J12: OFF | Q12: =IF($E12=Q$8,1,0) -> 0 | R12: =IF($J12=Q$8,1,0) -> 0 | S12: =IF($E12=S$8,1,0) -> 0 | T12: =IF($J12=S$8,1,0) -> 0 | U12: =IF($E12=U$8,1,0) -> 0 | V12: =IF($J12=U$8,1,0) -> 0 | W12: =IF($E12=W$8,1,0) -> 0 | X12: =IF($J12=W$8,1,0) -> 0 | Y12: =IF($E12=Y$8,1,0) -> 0 | Z12: =IF($J12=Y$8,1,0) -> 0 | AA12: =IF($E12=AA$8,1,0) -> 0 | AB12: =IF($J12=AA$8,1,0) -> 1 | AC12: =IF($E12=AC$8,1,0) -> 0 | AD12: =IF($J12=AC$8,1,0) -> 0 | AE12: =IF($E12=AE$8,1,0) -> 0 | AF12: =IF($J12=AE$8,1,0) -> 0 | AG12: =IF($E12=AG$8,1,0) -> 1 | AH12: =IF($J12=AG$8,1,0) -> 0 | AI12: =IF($E12=AI$8,1,0) -> 0 | AJ12: =IF($J12=AI$8,1,0) -> 0 | AK12: =IF($E12=AK$8,1,0) -> 0 | AL12: =IF($J12=AK$8,1,0) -> 0 | AM12: =IF($E12=AM$8,1,0) -> 0 | AN12: =IF($J12=AM$8,1,0) -> 0 | AO12: =IF($E12=AO$8,1,0) -> 0 | AP12: =IF($J12=AO$8,1,0) -> 0 | AQ12: =IF($E12=AQ$8,1,0) -> 0 | AR12: =IF($J12=AQ$8,1,0) -> 0 | AS12: =IF($E12=AS$8,1,0) -> 0 | AT12: =IF($J12=AS$8,1,0) -> 0 | AU12: =IF($E12=AU$8,1,0) -> 0 | AV12: =IF($J12=AU$8,1,0) -> 0 | AW12: =IF($E12=AW$8,1,0) -> 0 | AX12: =IF($J12=AW$8,1,0) -> 0 | AY12: =IF($E12=AY$8,1,0) -> 0 | AZ12: =IF($J12=AY$8,1,0) -> 0 | BA12: =IF($E12=BA$8,1,0) -> 0 | BB12: =IF($J12=BA$8,1,0) -> 0 | BC12: =IF($E12=BC$8,1,0) -> 0 | BD12: =IF($J12=BC$8,1,0) -> 0 | BE12: =IF($E12=BE$8,1,0) -> 0 | BF12: =IF($J12=BE$8,1,0) -> 0 | BG12: =IF($E12=BG$8,1,0) -> 0 | BH12: =IF($J12=BG$8,1,0) -> 0 | BI12: =IF($E12=BI$8,1,0) -> 0 | BJ12: =IF($J12=BI$8,1,0) -> 0 | BK12: =IF($E12=BK$8,1,0) -> 0 | BL12: =IF($J12=BK$8,1,0) -> 0 | BM12: =IF($E12=BM$8,1,0) -> 0 | BN12: =IF($J12=BM$8,1,0) -> 0 | BO12: =IF($E12=BO$8,1,0) -> 0 | BP12: =IF($J12=BO$8,1,0) -> 0 | BQ12: =IF($E12=BQ$8,1,0) -> 0 | BR12: =IF($J12=BQ$8,1,0) -> 0 | BS12: =IF($E12=BS$8,1,0) -> 0 | BT12: =IF($J12=BS$8,1,0) -> 0 | BU12: =IF($E12=BU$8,1,0) -> 0 | BV12: =IF($J12=BU$8,1,0) -> 0 | BW12: =IF($E12=BW$8,1,0) -> 0 | BX12: =IF($J12=BW$8,1,0) -> 0 | BY12: =IF($E12=BY$8,1,0) -> 0 | BZ12: =IF($J12=BY$8,1,0) -> 0 | CA12: =IF($E12=CA$8,1,0) -> 0 | CB12: =IF($J12=CA$8,1,0) -> 0 | CC12: =IF($E12=CC$8,1,0) -> 0 | CD12: =IF($J12=CC$8,1,0) -> 0 | CE12: =IF($E12=CE$8,1,0) -> 0 | CF12: =IF($J12=CE$8,1,0) -> 0 | CG12: =IF($E12=CG$8,1,0) -> 0 | CH12: =IF($J12=CG$8,1,0) -> 0 | CI12: =IF($E12=CI$8,1,0) -> 0 | CJ12: =IF($J12=CI$8,1,0) -> 0 | CK12: =IF($E12=CK$8,1,0) -> 0 | CL12: =IF($J12=CK$8,1,0) -> 0 | CM12: =IF($E12=CM$8,1,0) -> 0 | CN12: =IF($J12=CM$8,1,0) -> 0 | CO12: =IF($E12=CO$8,1,0) -> 0 | CP12: =IF($J12=CO$8,1,0) -> 0 | CQ12: =IF($E12=CQ$8,1,0) -> 0 | CR12: =IF($J12=CQ$8,1,0) -> 0 | CS12: =(SUM(Q12:CL12))+(SUM(Q12:CR12)) -> 4 | CT12: =IFERROR((VLOOKUP(A12,'Quad-Tech'!$F$1:$G$17,2,FALSE)),0) -> 0
A13: =A12+1 -> 44990 | D13: =VLOOKUP(A13,'Quad-Tech'!A6:B370,2,FALSE) -> Sun | E13: PH | J13: PH | Q13: =IF($E13=Q$8,1,0) -> 0 | R13: =IF($J13=Q$8,1,0) -> 0 | S13: =IF($E13=S$8,1,0) -> 1 | T13: =IF($J13=S$8,1,0) -> 1 | U13: =IF($E13=U$8,1,0) -> 0 | V13: =IF($J13=U$8,1,0) -> 0 | W13: =IF($E13=W$8,1,0) -> 0 | X13: =IF($J13=W$8,1,0) -> 0 | Y13: =IF($E13=Y$8,1,0) -> 0 | Z13: =IF($J13=Y$8,1,0) -> 0 | AA13: =IF($E13=AA$8,1,0) -> 0 | AB13: =IF($J13=AA$8,1,0) -> 0 | AC13: =IF($E13=AC$8,1,0) -> 0 | AD13: =IF($J13=AC$8,1,0) -> 0 | AE13: =IF($E13=AE$8,1,0) -> 0 | AF13: =IF($J13=AE$8,1,0) -> 0 | AG13: =IF($E13=AG$8,1,0) -> 0 | AH13: =IF($J13=AG$8,1,0) -> 0 | AI13: =IF($E13=AI$8,1,0) -> 0 | AJ13: =IF($J13=AI$8,1,0) -> 0 | AK13: =IF($E13=AK$8,1,0) -> 0 | AL13: =IF($J13=AK$8,1,0) -> 0 | AM13: =IF($E13=AM$8,1,0) -> 0 | AN13: =IF($J13=AM$8,1,0) -> 0 | AO13: =IF($E13=AO$8,1,0) -> 0 | AP13: =IF($J13=AO$8,1,0) -> 0 | AQ13: =IF($E13=AQ$8,1,0) -> 0 | AR13: =IF($J13=AQ$8,1,0) -> 0 | AS13: =IF($E13=AS$8,1,0) -> 0 | AT13: =IF($J13=AS$8,1,0) -> 0 | AU13: =IF($E13=AU$8,1,0) -> 0 | AV13: =IF($J13=AU$8,1,0) -> 0 | AW13: =IF($E13=AW$8,1,0) -> 0 | AX13: =IF($J13=AW$8,1,0) -> 0 | AY13: =IF($E13=AY$8,1,0) -> 0 | AZ13: =IF($J13=AY$8,1,0) -> 0 | BA13: =IF($E13=BA$8,1,0) -> 0 | BB13: =IF($J13=BA$8,1,0) -> 0 | BC13: =IF($E13=BC$8,1,0) -> 0 | BD13: =IF($J13=BC$8,1,0) -> 0 | BE13: =IF($E13=BE$8,1,0) -> 0 | BF13: =IF($J13=BE$8,1,0) -> 0 | BG13: =IF($E13=BG$8,1,0) -> 0 | BH13: =IF($J13=BG$8,1,0) -> 0 | BI13: =IF($E13=BI$8,1,0) -> 0 | BJ13: =IF($J13=BI$8,1,0) -> 0 | BK13: =IF($E13=BK$8,1,0) -> 0 | BL13: =IF($J13=BK$8,1,0) -> 0 | BM13: =IF($E13=BM$8,1,0) -> 0 | BN13: =IF($J13=BM$8,1,0) -> 0 | BO13: =IF($E13=BO$8,1,0) -> 0 | BP13: =IF($J13=BO$8,1,0) -> 0 | BQ13: =IF($E13=BQ$8,1,0) -> 0 | BR13: =IF($J13=BQ$8,1,0) -> 0 | BS13: =IF($E13=BS$8,1,0) -> 0 | BT13: =IF($J13=BS$8,1,0) -> 0 | BU13: =IF($E13=BU$8,1,0) -> 0 | BV13: =IF($J13=BU$8,1,0) -> 0 | BW13: =IF($E13=BW$8,1,0) -> 0 | BX13: =IF($J13=BW$8,1,0) -> 0 | BY13: =IF($E13=BY$8,1,0) -> 0 | BZ13: =IF($J13=BY$8,1,0) -> 0 | CA13: =IF($E13=CA$8,1,0) -> 0 | CB13: =IF($J13=CA$8,1,0) -> 0 | CC13: =IF($E13=CC$8,1,0) -> 0 | CD13: =IF($J13=CC$8,1,0) -> 0 | CE13: =IF($E13=CE$8,1,0) -> 0 | CF13: =IF($J13=CE$8,1,0) -> 0 | CG13: =IF($E13=CG$8,1,0) -> 0 | CH13: =IF($J13=CG$8,1,0) -> 0 | CI13: =IF($E13=CI$8,1,0) -> 0 | CJ13: =IF($J13=CI$8,1,0) -> 0 | CK13: =IF($E13=CK$8,1,0) -> 0 | CL13: =IF($J13=CK$8,1,0) -> 0 | CM13: =IF($E13=CM$8,1,0) -> 0 | CN13: =IF($J13=CM$8,1,0) -> 0 | CO13: =IF($E13=CO$8,1,0) -> 0 | CP13: =IF($J13=CO$8,1,0) -> 0 | CQ13: =IF($E13=CQ$8,1,0) -> 0 | CR13: =IF($J13=CQ$8,1,0) -> 0 | CS13: =(SUM(Q13:CL13))+(SUM(Q13:CR13)) -> 4 | CT13: =IFERROR((VLOOKUP(A13,'Quad-Tech'!$F$1:$G$17,2,FALSE)),0) -> 0
A14: =A13+1 -> 44991 | D14: =VLOOKUP(A14,'Quad-Tech'!A7:B371,2,FALSE) -> Mon | E14: 1735EM22W | J14: 1735EM22W | Q14: =IF($E14=Q$8,1,0) -> 0 | R14: =IF($J14=Q$8,1,0) -> 0 | S14: =IF($E14=S$8,1,0) -> 0 | T14: =IF($J14=S$8,1,0) -> 0 | U14: =IF($E14=U$8,1,0) -> 0 | V14: =IF($J14=U$8,1,0) -> 0 | W14: =IF($E14=W$8,1,0) -> 0 | X14: =IF($J14=W$8,1,0) -> 0 | Y14: =IF($E14=Y$8,1,0) -> 0 | Z14: =IF($J14=Y$8,1,0) -> 0 | AA14: =IF($E14=AA$8,1,0) -> 0 | AB14: =IF($J14=AA$8,1,0) -> 0 | AC14: =IF($E14=AC$8,1,0) -> 0 | AD14: =IF($J14=AC$8,1,0) -> 0 | AE14: =IF($E14=AE$8,1,0) -> 0 | AF14: =IF($J14=AE$8,1,0) -> 0 | AG14: =IF($E14=AG$8,1,0) -> 0 | AH14: =IF($J14=AG$8,1,0) -> 0 | AI14: =IF($E14=AI$8,1,0) -> 0 | AJ14: =IF($J14=AI$8,1,0) -> 0 | AK14: =IF($E14=AK$8,1,0) -> 0 | AL14: =IF($J14=AK$8,1,0) -> 0 | AM14: =IF($E14=AM$8,1,0) -> 0 | AN14: =IF($J14=AM$8,1,0) -> 0 | AO14: =IF($E14=AO$8,1,0) -> 0 | AP14: =IF($J14=AO$8,1,0) -> 0 | AQ14: =IF($E14=AQ$8,1,0) -> 0 | AR14: =IF($J14=AQ$8,1,0) -> 0 | AS14: =IF($E14=AS$8,1,0) -> 1 | AT14: =IF($J14=AS$8,1,0) -> 1 | AU14: =IF($E14=AU$8,1,0) -> 0 | AV14: =IF($J14=AU$8,1,0) -> 0 | AW14: =IF($E14=AW$8,1,0) -> 0 | AX14: =IF($J14=AW$8,1,0) -> 0 | AY14: =IF($E14=AY$8,1,0) -> 0 | AZ14: =IF($J14=AY$8,1,0) -> 0 | BA14: =IF($E14=BA$8,1,0) -> 0 | BB14: =IF($J14=BA$8,1,0) -> 0 | BC14: =IF($E14=BC$8,1,0) -> 0 | BD14: =IF($J14=BC$8,1,0) -> 0 | BE14: =IF($E14=BE$8,1,0) -> 0 | BF14: =IF($J14=BE$8,1,0) -> 0 | BG14: =IF($E14=BG$8,1,0) -> 0 | BH14: =IF($J14=BG$8,1,0) -> 0 | BI14: =IF($E14=BI$8,1,0) -> 0 | BJ14: =IF($J14=BI$8,1,0) -> 0 | BK14: =IF($E14=BK$8,1,0) -> 0 | BL14: =IF($J14=BK$8,1,0) -> 0 | BM14: =IF($E14=BM$8,1,0) -> 0 | BN14: =IF($J14=BM$8,1,0) -> 0 | BO14: =IF($E14=BO$8,1,0) -> 0 | BP14: =IF($J14=BO$8,1,0) -> 0 | BQ14: =IF($E14=BQ$8,1,0) -> 0 | BR14: =IF($J14=BQ$8,1,0) -> 0 | BS14: =IF($E14=BS$8,1,0) -> 0 | BT14: =IF($J14=BS$8,1,0) -> 0 | BU14: =IF($E14=BU$8,1,0) -> 0 | BV14: =IF($J14=BU$8,1,0) -> 0 | BW14: =IF($E14=BW$8,1,0) -> 0 | BX14: =IF($J14=BW$8,1,0) -> 0 | BY14: =IF($E14=BY$8,1,0) -> 0 | BZ14: =IF($J14=BY$8,1,0) -> 0 | CA14: =IF($E14=CA$8,1,0) -> 0 | CB14: =IF($J14=CA$8,1,0) -> 0 | CC14: =IF($E14=CC$8,1,0) -> 0 | CD14: =IF($J14=CC$8,1,0) -> 0 | CE14: =IF($E14=CE$8,1,0) -> 0 | CF14: =IF($J14=CE$8,1,0) -> 0 | CG14: =IF($E14=CG$8,1,0) -> 0 | CH14: =IF($J14=CG$8,1,0) -> 0 | CI14: =IF($E14=CI$8,1,0) -> 0 | CJ14: =IF($J14=CI$8,1,0) -> 0 | CK14: =IF($E14=CK$8,1,0) -> 0 | CL14: =IF($J14=CK$8,1,0) -> 0 | CM14: =IF($E14=CM$8,1,0) -> 0 | CN14: =IF($J14=CM$8,1,0) -> 0 | CO14: =IF($E14=CO$8,1,0) -> 0 | CP14: =IF($J14=CO$8,1,0) -> 0 | CQ14: =IF($E14=CQ$8,1,0) -> 0 | CR14: =IF($J14=CQ$8,1,0) -> 0 | CS14: =(SUM(Q14:CL14))+(SUM(Q14:CR14)) -> 4 | CT14: =IFERROR((VLOOKUP(A14,'Quad-Tech'!$F$1:$G$17,2,FALSE)),0) -> 0
A15: =A14+1 -> 44992 | D15: =VLOOKUP(A15,'Quad-Tech'!A8:B372,2,FALSE) -> Tue | E15: Kai Tak 1B2 | J15: Kai Tak 1B2 | Q15: =IF($E15=Q$8,1,0) -> 0 | R15: =IF($J15=Q$8,1,0) -> 0 | S15: =IF($E15=S$8,1,0) -> 0 | T15: =IF($J15=S$8,1,0) -> 0 | U15: =IF($E15=U$8,1,0) -> 0 | V15: =IF($J15=U$8,1,0) -> 0 | W15: =IF($E15=W$8,1,0) -> 0 | X15: =IF($J15=W$8,1,0) -> 0 | Y15: =IF($E15=Y$8,1,0) -> 0 | Z15: =IF($J15=Y$8,1,0) -> 0 | AA15: =IF($E15=AA$8,1,0) -> 0 | AB15: =IF($J15=AA$8,1,0) -> 0 | AC15: =IF($E15=AC$8,1,0) -> 0 | AD15: =IF($J15=AC$8,1,0) -> 0 | AE15: =IF($E15=AE$8,1,0) -> 0 | AF15: =IF($J15=AE$8,1,0) -> 0 | AG15: =IF($E15=AG$8,1,0) -> 0 | AH15: =IF($J15=AG$8,1,0) -> 0 | AI15: =IF($E15=AI$8,1,0) -> 0 | AJ15: =IF($J15=AI$8,1,0) -> 0 | AK15: =IF($E15=AK$8,1,0) -> 0 | AL15: =IF($J15=AK$8,1,0) -> 0 | AM15: =IF($E15=AM$8,1,0) -> 0 | AN15: =IF($J15=AM$8,1,0) -> 0 | AO15: =IF($E15=AO$8,1,0) -> 0 | AP15: =IF($J15=AO$8,1,0) -> 0 | AQ15: =IF($E15=AQ$8,1,0) -> 0 | AR15: =IF($J15=AQ$8,1,0) -> 0 | AS15: =IF($E15=AS$8,1,0) -> 0 | AT15: =IF($J15=AS$8,1,0) -> 0 | AU15: =IF($E15=AU$8,1,0) -> 0 | AV15: =IF($J15=AU$8,1,0) -> 0 | AW15: =IF($E15=AW$8,1,0) -> 1 | AX15: =IF($J15=AW$8,1,0) -> 1 | AY15: =IF($E15=AY$8,1,0) -> 0 | AZ15: =IF($J15=AY$8,1,0) -> 0 | BA15: =IF($E15=BA$8,1,0) -> 0 | BB15: =IF($J15=BA$8,1,0) -> 0 | BC15: =IF($E15=BC$8,1,0) -> 0 | BD15: =IF($J15=BC$8,1,0) -> 0 | BE15: =IF($E15=BE$8,1,0) -> 0 | BF15: =IF($J15=BE$8,1,0) -> 0 | BG15: =IF($E15=BG$8,1,0) -> 0 | BH15: =IF($J15=BG$8,1,0) -> 0 | BI15: =IF($E15=BI$8,1,0) -> 0 | BJ15: =IF($J15=BI$8,1,0) -> 0 | BK15: =IF($E15=BK$8,1,0) -> 0 | BL15: =IF($J15=BK$8,1,0) -> 0 | BM15: =IF($E15=BM$8,1,0) -> 0 | BN15: =IF($J15=BM$8,1,0) -> 0 | BO15: =IF($E15=BO$8,1,0) -> 0 | BP15: =IF($J15=BO$8,1,0) -> 0 | BQ15: =IF($E15=BQ$8,1,0) -> 0 | BR15: =IF($J15=BQ$8,1,0) -> 0 | BS15: =IF($E15=BS$8,1,0) -> 0 | BT15: =IF($J15=BS$8,1,0) -> 0 | BU15: =IF($E15=BU$8,1,0) -> 0 | BV15: =IF($J15=BU$8,1,0) -> 0 | BW15: =IF($E15=BW$8,1,0) -> 0 | BX15: =IF($J15=BW$8,1,0) -> 0 | BY15: =IF($E15=BY$8,1,0) -> 0 | BZ15: =IF($J15=BY$8,1,0) -> 0 | CA15: =IF($E15=CA$8,1,0) -> 0 | CB15: =IF($J15=CA$8,1,0) -> 0 | CC15: =IF($E15=CC$8,1,0) -> 0 | CD15: =IF($J15=CC$8,1,0) -> 0 | CE15: =IF($E15=CE$8,1,0) -> 0 | CF15: =IF($J15=CE$8,1,0) -> 0 | CG15: =IF($E15=CG$8,1,0) -> 0 | CH15: =IF($J15=CG$8,1,0) -> 0 | CI15: =IF($E15=CI$8,1,0) -> 0 | CJ15: =IF($J15=CI$8,1,0) -> 0 | CK15: =IF($E15=CK$8,1,0) -> 0 | CL15: =IF($J15=CK$8,1,0) -> 0 | CM15: =IF($E15=CM$8,1,0) -> 0 | CN15: =IF($J15=CM$8,1,0) -> 0 | CO15: =IF($E15=CO$8,1,0) -> 0 | CP15: =IF($J15=CO$8,1,0) -> 0 | CQ15: =IF($E15=CQ$8,1,0) -> 0 | CR15: =IF($J15=CQ$8,1,0) -> 0 | CS15: =(SUM(Q15:CL15))+(SUM(Q15:CR15)) -> 4 | CT15: =IFERROR((VLOOKUP(A15,'Quad-Tech'!$F$1:$G$17,2,FALSE)),0) -> 0
A16: =A15+1 -> 44993 | D16: =VLOOKUP(A16,'Quad-Tech'!A9:B373,2,FALSE) -> Wed | E16: Kai Tak 1B2 | J16: Kai Tak 1B2 | Q16: =IF($E16=Q$8,1,0) -> 0 | R16: =IF($J16=Q$8,1,0) -> 0 | S16: =IF($E16=S$8,1,0) -> 0 | T16: =IF($J16=S$8,1,0) -> 0 | U16: =IF($E16=U$8,1,0) -> 0 | V16: =IF($J16=U$8,1,0) -> 0 | W16: =IF($E16=W$8,1,0) -> 0 | X16: =IF($J16=W$8,1,0) -> 0 | Y16: =IF($E16=Y$8,1,0) -> 0 | Z16: =IF($J16=Y$8,1,0) -> 0 | AA16: =IF($E16=AA$8,1,0) -> 0 | AB16: =IF($J16=AA$8,1,0) -> 0 | AC16: =IF($E16=AC$8,1,0) -> 0 | AD16: =IF($J16=AC$8,1,0) -> 0 | AE16: =IF($E16=AE$8,1,0) -> 0 | AF16: =IF($J16=AE$8,1,0) -> 0 | AG16: =IF($E16=AG$8,1,0) -> 0 | AH16: =IF($J16=AG$8,1,0) -> 0 | AI16: =IF($E16=AI$8,1,0) -> 0 | AJ16: =IF($J16=AI$8,1,0) -> 0 | AK16: =IF($E16=AK$8,1,0) -> 0 | AL16: =IF($J16=AK$8,1,0) -> 0 | AM16: =IF($E16=AM$8,1,0) -> 0 | AN16: =IF($J16=AM$8,1,0) -> 0 | AO16: =IF($E16=AO$8,1,0) -> 0 | AP16: =IF($J16=AO$8,1,0) -> 0 | AQ16: =IF($E16=AQ$8,1,0) -> 0 | AR16: =IF($J16=AQ$8,1,0) -> 0 | AS16: =IF($E16=AS$8,1,0) -> 0 | AT16: =IF($J16=AS$8,1,0) -> 0 | AU16: =IF($E16=AU$8,1,0) -> 0 | AV16: =IF($J16=AU$8,1,0) -> 0 | AW16: =IF($E16=AW$8,1,0) -> 1 | AX16: =IF($J16=AW$8,1,0) -> 1 | AY16: =IF($E16=AY$8,1,0) -> 0 | AZ16: =IF($J16=AY$8,1,0) -> 0 | BA16: =IF($E16=BA$8,1,0) -> 0 | BB16: =IF($J16=BA$8,1,0) -> 0 | BC16: =IF($E16=BC$8,1,0) -> 0 | BD16: =IF($J16=BC$8,1,0) -> 0 | BE16: =IF($E16=BE$8,1,0) -> 0 | BF16: =IF($J16=BE$8,1,0) -> 0 | BG16: =IF($E16=BG$8,1,0) -> 0 | BH16: =IF($J16=BG$8,1,0) -> 0 | BI16: =IF($E16=BI$8,1,0) -> 0 | BJ16: =IF($J16=BI$8,1,0) -> 0 | BK16: =IF($E16=BK$8,1,0) -> 0 | BL16: =IF($J16=BK$8,1,0) -> 0 | BM16: =IF($E16=BM$8,1,0) -> 0 | BN16: =IF($J16=BM$8,1,0) -> 0 | BO16: =IF($E16=BO$8,1,0) -> 0 | BP16: =IF($J16=BO$8,1,0) -> 0 | BQ16: =IF($E16=BQ$8,1,0) -> 0 | BR16: =IF($J16=BQ$8,1,0) -> 0 | BS16: =IF($E16=BS$8,1,0) -> 0 | BT16: =IF($J16=BS$8,1,0) -> 0 | BU16: =IF($E16=BU$8,1,0) -> 0 | BV16: =IF($J16=BU$8,1,0) -> 0 | BW16: =IF($E16=BW$8,1,0) -> 0 | BX16: =IF($J16=BW$8,1,0) -> 0 | BY16: =IF($E16=BY$8,1,0) -> 0 | BZ16: =IF($J16=BY$8,1,0) -> 0 | CA16: =IF($E16=CA$8,1,0) -> 0 | CB16: =IF($J16=CA$8,1,0) -> 0 | CC16: =IF($E16=CC$8,1,0) -> 0 | CD16: =IF($J16=CC$8,1,0) -> 0 | CE16: =IF($E16=CE$8,1,0) -> 0 | CF16: =IF($J16=CE$8,1,0) -> 0 | CG16: =IF($E16=CG$8,1,0) -> 0 | CH16: =IF($J16=CG$8,1,0) -> 0 | CI16: =IF($E16=CI$8,1,0) -> 0 | CJ16: =IF($J16=CI$8,1,0) -> 0 | CK16: =IF($E16=CK$8,1,0) -> 0 | CL16: =IF($J16=CK$8,1,0) -> 0 | CM16: =IF($E16=CM$8,1,0) -> 0 | CN16: =IF($J16=CM$8,1,0) -> 0 | CO16: =IF($E16=CO$8,1,0) -> 0 | CP16: =IF($J16=CO$8,1,0) -> 0 | CQ16: =IF($E16=CQ$8,1,0) -> 0 | CR16: =IF($J16=CQ$8,1,0) -> 0 | CS16: =(SUM(Q16:CL16))+(SUM(Q16:CR16)) -> 4 | CT16: =IFERROR((VLOOKUP(A16,'Quad-Tech'!$F$1:$G$17,2,FALSE)),0) -> 0
A17: =A16+1 -> 44994 | D17: =VLOOKUP(A17,'Quad-Tech'!A10:B374,2,FALSE) -> Thu | E17: Kai Tak 1B2 | J17: Kai Tak 1B2 | Q17: =IF($E17=Q$8,1,0) -> 0 | R17: =IF($J17=Q$8,1,0) -> 0 | S17: =IF($E17=S$8,1,0) -> 0 | T17: =IF($J17=S$8,1,0) -> 0 | U17: =IF($E17=U$8,1,0) -> 0 | V17: =IF($J17=U$8,1,0) -> 0 | W17: =IF($E17=W$8,1,0) -> 0 | X17: =IF($J17=W$8,1,0) -> 0 | Y17: =IF($E17=Y$8,1,0) -> 0 | Z17: =IF($J17=Y$8,1,0) -> 0 | AA17: =IF($E17=AA$8,1,0) -> 0 | AB17: =IF($J17=AA$8,1,0) -> 0 | AC17: =IF($E17=AC$8,1,0) -> 0 | AD17: =IF($J17=AC$8,1,0) -> 0 | AE17: =IF($E17=AE$8,1,0) -> 0 | AF17: =IF($J17=AE$8,1,0) -> 0 | AG17: =IF($E17=AG$8,1,0) -> 0 | AH17: =IF($J17=AG$8,1,0) -> 0 | AI17: =IF($E17=AI$8,1,0) -> 0 | AJ17: =IF($J17=AI$8,1,0) -> 0 | AK17: =IF($E17=AK$8,1,0) -> 0 | AL17: =IF($J17=AK$8,1,0) -> 0 | AM17: =IF($E17=AM$8,1,0) -> 0 | AN17: =IF($J17=AM$8,1,0) -> 0 | AO17: =IF($E17=AO$8,1,0) -> 0 | AP17: =IF($J17=AO$8,1,0) -> 0 | AQ17: =IF($E17=AQ$8,1,0) -> 0 | AR17: =IF($J17=AQ$8,1,0) -> 0 | AS17: =IF($E17=AS$8,1,0) -> 0 | AT17: =IF($J17=AS$8,1,0) -> 0 | AU17: =IF($E17=AU$8,1,0) -> 0 | AV17: =IF($J17=AU$8,1,0) -> 0 | AW17: =IF($E17=AW$8,1,0) -> 1 | AX17: =IF($J17=AW$8,1,0) -> 1 | AY17: =IF($E17=AY$8,1,0) -> 0 | AZ17: =IF($J17=AY$8,1,0) -> 0 | BA17: =IF($E17=BA$8,1,0) -> 0 | BB17: =IF($J17=BA$8,1,0) -> 0 | BC17: =IF($E17=BC$8,1,0) -> 0 | BD17: =IF($J17=BC$8,1,0) -> 0 | BE17: =IF($E17=BE$8,1,0) -> 0 | BF17: =IF($J17=BE$8,1,0) -> 0 | BG17: =IF($E17=BG$8,1,0) -> 0 | BH17: =IF($J17=BG$8,1,0) -> 0 | BI17: =IF($E17=BI$8,1,0) -> 0 | BJ17: =IF($J17=BI$8,1,0) -> 0 | BK17: =IF($E17=BK$8,1,0) -> 0 | BL17: =IF($J17=BK$8,1,0) -> 0 | BM17: =IF($E17=BM$8,1,0) -> 0 | BN17: =IF($J17=BM$8,1,0) -> 0 | BO17: =IF($E17=BO$8,1,0) -> 0 | BP17: =IF($J17=BO$8,1,0) -> 0 | BQ17: =IF($E17=BQ$8,1,0) -> 0 | BR17: =IF($J17=BQ$8,1,0) -> 0 | BS17: =IF($E17=BS$8,1,0) -> 0 | BT17: =IF($J17=BS$8,1,0) -> 0 | BU17: =IF($E17=BU$8,1,0) -> 0 | BV17: =IF($J17=BU$8,1,0) -> 0 | BW17: =IF($E17=BW$8,1,0) -> 0 | BX17: =IF($J17=BW$8,1,0) -> 0 | BY17: =IF($E17=BY$8,1,0) -> 0 | BZ17: =IF($J17=BY$8,1,0) -> 0 | CA17: =IF($E17=CA$8,1,0) -> 0 | CB17: =IF($J17=CA$8,1,0) -> 0 | CC17: =IF($E17=CC$8,1,0) -> 0 | CD17: =IF($J17=CC$8,1,0) -> 0 | CE17: =IF($E17=CE$8,1,0) -> 0 | CF17: =IF($J17=CE$8,1,0) -> 0 | CG17: =IF($E17=CG$8,1,0) -> 0 | CH17: =IF($J17=CG$8,1,0) -> 0 | CI17: =IF($E17=CI$8,1,0) -> 0 | CJ17: =IF($J17=CI$8,1,0) -> 0 | CK17: =IF($E17=CK$8,1,0) -> 0 | CL17: =IF($J17=CK$8,1,0) -> 0 | CM17: =IF($E17=CM$8,1,0) -> 0 | CN17: =IF($J17=CM$8,1,0) -> 0 | CO17: =IF($E17=CO$8,1,0) -> 0 | CP17: =IF($J17=CO$8,1,0) -> 0 | CQ17: =IF($E17=CQ$8,1,0) -> 0 | CR17: =IF($J17=CQ$8,1,0) -> 0 | CS17: =(SUM(Q17:CL17))+(SUM(Q17:CR17)) -> 4 | CT17: =IFERROR((VLOOKUP(A17,'Quad-Tech'!$F$1:$G$17,2,FALSE)),0) -> 0
A18: =A17+1 -> 44995 | D18: =VLOOKUP(A18,'Quad-Tech'!A11:B375,2,FALSE) -> Fri | E18: Kai Tak 1B2 | J18: Kai Tak 1B2 | Q18: =IF($E18=Q$8,1,0) -> 0 | R18: =IF($J18=Q$8,1,0) -> 0 | S18: =IF($E18=S$8,1,0) -> 0 | T18: =IF($J18=S$8,1,0) -> 0 | U18: =IF($E18=U$8,1,0) -> 0 | V18: =IF($J18=U$8,1,0) -> 0 | W18: =IF($E18=W$8,1,0) -> 0 | X18: =IF($J18=W$8,1,0) -> 0 | Y18: =IF($E18=Y$8,1,0) -> 0 | Z18: =IF($J18=Y$8,1,0) -> 0 | AA18: =IF($E18=AA$8,1,0) -> 0 | AB18: =IF($J18=AA$8,1,0) -> 0 | AC18: =IF($E18=AC$8,1,0) -> 0 | AD18: =IF($J18=AC$8,1,0) -> 0 | AE18: =IF($E18=AE$8,1,0) -> 0 | AF18: =IF($J18=AE$8,1,0) -> 0 | AG18: =IF($E18=AG$8,1,0) -> 0 | AH18: =IF($J18=AG$8,1,0) -> 0 | AI18: =IF($E18=AI$8,1,0) -> 0 | AJ18: =IF($J18=AI$8,1,0) -> 0 | AK18: =IF($E18=AK$8,1,0) -> 0 | AL18: =IF($J18=AK$8,1,0) -> 0 | AM18: =IF($E18=AM$8,1,0) -> 0 | AN18: =IF($J18=AM$8,1,0) -> 0 | AO18: =IF($E18=AO$8,1,0) -> 0 | AP18: =IF($J18=AO$8,1,0) -> 0 | AQ18: =IF($E18=AQ$8,1,0) -> 0 | AR18: =IF($J18=AQ$8,1,0) -> 0 | AS18: =IF($E18=AS$8,1,0) -> 0 | AT18: =IF($J18=AS$8,1,0) -> 0 | AU18: =IF($E18=AU$8,1,0) -> 0 | AV18: =IF($J18=AU$8,1,0) -> 0 | AW18: =IF($E18=AW$8,1,0) -> 1 | AX18: =IF($J18=AW$8,1,0) -> 1 | AY18: =IF($E18=AY$8,1,0) -> 0 | AZ18: =IF($J18=AY$8,1,0) -> 0 | BA18: =IF($E18=BA$8,1,0) -> 0 | BB18: =IF($J18=BA$8,1,0) -> 0 | BC18: =IF($E18=BC$8,1,0) -> 0 | BD18: =IF($J18=BC$8,1,0) -> 0 | BE18: =IF($E18=BE$8,1,0) -> 0 | BF18: =IF($J18=BE$8,1,0) -> 0 | BG18: =IF($E18=BG$8,1,0) -> 0 | BH18: =IF($J18=BG$8,1,0) -> 0 | BI18: =IF($E18=BI$8,1,0) -> 0 | BJ18: =IF($J18=BI$8,1,0) -> 0 | BK18: =IF($E18=BK$8,1,0) -> 0 | BL18: =IF($J18=BK$8,1,0) -> 0 | BM18: =IF($E18=BM$8,1,0) -> 0 | BN18: =IF($J18=BM$8,1,0) -> 0 | BO18: =IF($E18=BO$8,1,0) -> 0 | BP18: =IF($J18=BO$8,1,0) -> 0 | BQ18: =IF($E18=BQ$8,1,0) -> 0 | BR18: =IF($J18=BQ$8,1,0) -> 0 | BS18: =IF($E18=BS$8,1,0) -> 0 | BT18: =IF($J18=BS$8,1,0) -> 0 | BU18: =IF($E18=BU$8,1,0) -> 0 | BV18: =IF($J18=BU$8,1,0) -> 0 | BW18: =IF($E18=BW$8,1,0) -> 0 | BX18: =IF($J18=BW$8,1,0) -> 0 | BY18: =IF($E18=BY$8,1,0) -> 0 | BZ18: =IF($J18=BY$8,1,0) -> 0 | CA18: =IF($E18=CA$8,1,0) -> 0 | CB18: =IF($J18=CA$8,1,0) -> 0 | CC18: =IF($E18=CC$8,1,0) -> 0 | CD18: =IF($J18=CC$8,1,0) -> 0 | CE18: =IF($E18=CE$8,1,0) -> 0 | CF18: =IF($J18=CE$8,1,0) -> 0 | CG18: =IF($E18=CG$8,1,0) -> 0 | CH18: =IF($J18=CG$8,1,0) -> 0 | CI18: =IF($E18=CI$8,1,0) -> 0 | CJ18: =IF($J18=CI$8,1,0) -> 0 | CK18: =IF($E18=CK$8,1,0) -> 0 | CL18: =IF($J18=CK$8,1,0) -> 0 | CM18: =IF($E18=CM$8,1,0) -> 0 | CN18: =IF($J18=CM$8,1,0) -> 0 | CO18: =IF($E18=CO$8,1,0) -> 0 | CP18: =IF($J18=CO$8,1,0) -> 0 | CQ18: =IF($E18=CQ$8,1,0) -> 0 | CR18: =IF($J18=CQ$8,1,0) -> 0 | CS18: =(SUM(Q18:CL18))+(SUM(Q18:CR18)) -> 4 | CT18: =IFERROR((VLOOKUP(A18,'Quad-Tech'!$F$1:$G$17,2,FALSE)),0) -> 0
A19: =A18+1 -> 44996 | D19: =VLOOKUP(A19,'Quad-Tech'!A12:B376,2,FALSE) -> Sat | E19: OFF | J19: OFF | Q19: =IF($E19=Q$8,1,0) -> 0 | R19: =IF($J19=Q$8,1,0) -> 0 | S19: =IF($E19=S$8,1,0) -> 0 | T19: =IF($J19=S$8,1,0) -> 0 | U19: =IF($E19=U$8,1,0) -> 0 | V19: =IF($J19=U$8,1,0) -> 0 | W19: =IF($E19=W$8,1,0) -> 0 | X19: =IF($J19=W$8,1,0) -> 0 | Y19: =IF($E19=Y$8,1,0) -> 0 | Z19: =IF($J19=Y$8,1,0) -> 0 | AA19: =IF($E19=AA$8,1,0) -> 1 | AB19: =IF($J19=AA$8,1,0) -> 1 | AC19: =IF($E19=AC$8,1,0) -> 0 | AD19: =IF($J19=AC$8,1,0) -> 0 | AE19: =IF($E19=AE$8,1,0) -> 0 | AF19: =IF($J19=AE$8,1,0) -> 0 | AG19: =IF($E19=AG$8,1,0) -> 0 | AH19: =IF($J19=AG$8,1,0) -> 0 | AI19: =IF($E19=AI$8,1,0) -> 0 | AJ19: =IF($J19=AI$8,1,0) -> 0 | AK19: =IF($E19=AK$8,1,0) -> 0 | AL19: =IF($J19=AK$8,1,0) -> 0 | AM19: =IF($E19=AM$8,1,0) -> 0 | AN19: =IF($J19=AM$8,1,0) -> 0 | AO19: =IF($E19=AO$8,1,0) -> 0 | AP19: =IF($J19=AO$8,1,0) -> 0 | AQ19: =IF($E19=AQ$8,1,0) -> 0 | AR19: =IF($J19=AQ$8,1,0) -> 0 | AS19: =IF($E19=AS$8,1,0) -> 0 | AT19: =IF($J19=AS$8,1,0) -> 0 | AU19: =IF($E19=AU$8,1,0) -> 0 | AV19: =IF($J19=AU$8,1,0) -> 0 | AW19: =IF($E19=AW$8,1,0) -> 0 | AX19: =IF($J19=AW$8,1,0) -> 0 | AY19: =IF($E19=AY$8,1,0) -> 0 | AZ19: =IF($J19=AY$8,1,0) -> 0 | BA19: =IF($E19=BA$8,1,0) -> 0 | BB19: =IF($J19=BA$8,1,0) -> 0 | BC19: =IF($E19=BC$8,1,0) -> 0 | BD19: =IF($J19=BC$8,1,0) -> 0 | BE19: =IF($E19=BE$8,1,0) -> 0 | BF19: =IF($J19=BE$8,1,0) -> 0 | BG19: =IF($E19=BG$8,1,0) -> 0 | BH19: =IF($J19=BG$8,1,0) -> 0 | BI19: =IF($E19=BI$8,1,0) -> 0 | BJ19: =IF($J19=BI$8,1,0) -> 0 | BK19: =IF($E19=BK$8,1,0) -> 0 | BL19: =IF($J19=BK$8,1,0) -> 0 | BM19: =IF($E19=BM$8,1,0) -> 0 | BN19: =IF($J19=BM$8,1,0) -> 0 | BO19: =IF($E19=BO$8,1,0) -> 0 | BP19: =IF($J19=BO$8,1,0) -> 0 | BQ19: =IF($E19=BQ$8,1,0) -> 0 | BR19: =IF($J19=BQ$8,1,0) -> 0 | BS19: =IF($E19=BS$8,1,0) -> 0 | BT19: =IF($J19=BS$8,1,0) -> 0 | BU19: =IF($E19=BU$8,1,0) -> 0 | BV19: =IF($J19=BU$8,1,0) -> 0 | BW19: =IF($E19=BW$8,1,0) -> 0 | BX19: =IF($J19=BW$8,1,0) -> 0 | BY19: =IF($E19=BY$8,1,0) -> 0 | BZ19: =IF($J19=BY$8,1,0) -> 0 | CA19: =IF($E19=CA$8,1,0) -> 0 | CB19: =IF($J19=CA$8,1,0) -> 0 | CC19: =IF($E19=CC$8,1,0) -> 0 | CD19: =IF($J19=CC$8,1,0) -> 0 | CE19: =IF($E19=CE$8,1,0) -> 0 | CF19: =IF($J19=CE$8,1,0) -> 0 | CG19: =IF($E19=CG$8,1,0) -> 0 | CH19: =IF($J19=CG$8,1,0) -> 0 | CI19: =IF($E19=CI$8,1,0) -> 0 | CJ19: =IF($J19=CI$8,1,0) -> 0 | CK19: =IF($E19=CK$8,1,0) -> 0 | CL19: =IF($J19=CK$8,1,0) -> 0 | CM19: =IF($E19=CM$8,1,0) -> 0 | CN19: =IF($J19=CM$8,1,0) -> 0 | CO19: =IF($E19=CO$8,1,0) -> 0 | CP19: =IF($J19=CO$8,1,0) -> 0 | CQ19: =IF($E19=CQ$8,1,0) -> 0 | CR19: =IF($J19=CQ$8,1,0) -> 0 | CS19: =(SUM(Q19:CL19))+(SUM(Q19:CR19)) -> 4 | CT19: =IFERROR((VLOOKUP(A19,'Quad-Tech'!$F$1:$G$17,2,FALSE)),0) -> 0
A20: =A19+1 -> 44997 | D20: =VLOOKUP(A20,'Quad-Tech'!A13:B377,2,FALSE) -> Sun | E20: PH | J20: PH | Q20: =IF($E20=Q$8,1,0) -> 0 | R20: =IF($J20=Q$8,1,0) -> 0 | S20: =IF($E20=S$8,1,0) -> 1 | T20: =IF($J20=S$8,1,0) -> 1 | U20: =IF($E20=U$8,1,0) -> 0 | V20: =IF($J20=U$8,1,0) -> 0 | W20: =IF($E20=W$8,1,0) -> 0 | X20: =IF($J20=W$8,1,0) -> 0 | Y20: =IF($E20=Y$8,1,0) -> 0 | Z20: =IF($J20=Y$8,1,0) -> 0 | AA20: =IF($E20=AA$8,1,0) -> 0 | AB20: =IF($J20=AA$8,1,0) -> 0 | AC20: =IF($E20=AC$8,1,0) -> 0 | AD20: =IF($J20=AC$8,1,0) -> 0 | AE20: =IF($E20=AE$8,1,0) -> 0 | AF20: =IF($J20=AE$8,1,0) -> 0 | AG20: =IF($E20=AG$8,1,0) -> 0 | AH20: =IF($J20=AG$8,1,0) -> 0 | AI20: =IF($E20=AI$8,1,0) -> 0 | AJ20: =IF($J20=AI$8,1,0) -> 0 | AK20: =IF($E20=AK$8,1,0) -> 0 | AL20: =IF($J20=AK$8,1,0) -> 0 | AM20: =IF($E20=AM$8,1,0) -> 0 | AN20: =IF($J20=AM$8,1,0) -> 0 | AO20: =IF($E20=AO$8,1,0) -> 0 | AP20: =IF($J20=AO$8,1,0) -> 0 | AQ20: =IF($E20=AQ$8,1,0) -> 0 | AR20: =IF($J20=AQ$8,1,0) -> 0 | AS20: =IF($E20=AS$8,1,0) -> 0 | AT20: =IF($J20=AS$8,1,0) -> 0 | AU20: =IF($E20=AU$8,1,0) -> 0 | AV20: =IF($J20=AU$8,1,0) -> 0 | AW20: =IF($E20=AW$8,1,0) -> 0 | AX20: =IF($J20=AW$8,1,0) -> 0 | AY20: =IF($E20=AY$8,1,0) -> 0 | AZ20: =IF($J20=AY$8,1,0) -> 0 | BA20: =IF($E20=BA$8,1,0) -> 0 | BB20: =IF($J20=BA$8,1,0) -> 0 | BC20: =IF($E20=BC$8,1,0) -> 0 | BD20: =IF($J20=BC$8,1,0) -> 0 | BE20: =IF($E20=BE$8,1,0) -> 0 | BF20: =IF($J20=BE$8,1,0) -> 0 | BG20: =IF($E20=BG$8,1,0) -> 0 | BH20: =IF($J20=BG$8,1,0) -> 0 | BI20: =IF($E20=BI$8,1,0) -> 0 | BJ20: =IF($J20=BI$8,1,0) -> 0 | BK20: =IF($E20=BK$8,1,0) -> 0 | BL20: =IF($J20=BK$8,1,0) -> 0 | BM20: =IF($E20=BM$8,1,0) -> 0 | BN20: =IF($J20=BM$8,1,0) -> 0 | BO20: =IF($E20=BO$8,1,0) -> 0 | BP20: =IF($J20=BO$8,1,0) -> 0 | BQ20: =IF($E20=BQ$8,1,0) -> 0 | BR20: =IF($J20=BQ$8,1,0) -> 0 | BS20: =IF($E20=BS$8,1,0) -> 0 | BT20: =IF($J20=BS$8,1,0) -> 0 | BU20: =IF($E20=BU$8,1,0) -> 0 | BV20: =IF($J20=BU$8,1,0) -> 0 | BW20: =IF($E20=BW$8,1,0) -> 0 | BX20: =IF($J20=BW$8,1,0) -> 0 | BY20: =IF($E20=BY$8,1,0) -> 0 | BZ20: =IF($J20=BY$8,1,0) -> 0 | CA20: =IF($E20=CA$8,1,0) -> 0 | CB20: =IF($J20=CA$8,1,0) -> 0 | CC20: =IF($E20=CC$8,1,0) -> 0 | CD20: =IF($J20=CC$8,1,0) -> 0 | CE20: =IF($E20=CE$8,1,0) -> 0 | CF20: =IF($J20=CE$8,1,0) -> 0 | CG20: =IF($E20=CG$8,1,0) -> 0 | CH20: =IF($J20=CG$8,1,0) -> 0 | CI20: =IF($E20=CI$8,1,0) -> 0 | CJ20: =IF($J20=CI$8,1,0) -> 0 | CK20: =IF($E20=CK$8,1,0) -> 0 | CL20: =IF($J20=CK$8,1,0) -> 0 | CM20: =IF($E20=CM$8,1,0) -> 0 | CN20: =IF($J20=CM$8,1,0) -> 0 | CO20: =IF($E20=CO$8,1,0) -> 0 | CP20: =IF($J20=CO$8,1,0) -> 0 | CQ20: =IF($E20=CQ$8,1,0) -> 0 | CR20: =IF($J20=CQ$8,1,0) -> 0 | CS20: =(SUM(Q20:CL20))+(SUM(Q20:CR20)) -> 4 | CT20: =IFERROR((VLOOKUP(A20,'Quad-Tech'!$F$1:$G$17,2,FALSE)),0) -> 0
A21: =A20+1 -> 44998 | D21: =VLOOKUP(A21,'Quad-Tech'!A14:B378,2,FALSE) -> Mon | E21: 2656EM20M | J21: 2656EM20M | Q21: =IF($E21=Q$8,1,0) -> 0 | R21: =IF($J21=Q$8,1,0) -> 0 | S21: =IF($E21=S$8,1,0) -> 0 | T21: =IF($J21=S$8,1,0) -> 0 | U21: =IF($E21=U$8,1,0) -> 0 | V21: =IF($J21=U$8,1,0) -> 0 | W21: =IF($E21=W$8,1,0) -> 0 | X21: =IF($J21=W$8,1,0) -> 0 | Y21: =IF($E21=Y$8,1,0) -> 0 | Z21: =IF($J21=Y$8,1,0) -> 0 | AA21: =IF($E21=AA$8,1,0) -> 0 | AB21: =IF($J21=AA$8,1,0) -> 0 | AC21: =IF($E21=AC$8,1,0) -> 0 | AD21: =IF($J21=AC$8,1,0) -> 0 | AE21: =IF($E21=AE$8,1,0) -> 0 | AF21: =IF($J21=AE$8,1,0) -> 0 | AG21: =IF($E21=AG$8,1,0) -> 1 | AH21: =IF($J21=AG$8,1,0) -> 1 | AI21: =IF($E21=AI$8,1,0) -> 0 | AJ21: =IF($J21=AI$8,1,0) -> 0 | AK21: =IF($E21=AK$8,1,0) -> 0 | AL21: =IF($J21=AK$8,1,0) -> 0 | AM21: =IF($E21=AM$8,1,0) -> 0 | AN21: =IF($J21=AM$8,1,0) -> 0 | AO21: =IF($E21=AO$8,1,0) -> 0 | AP21: =IF($J21=AO$8,1,0) -> 0 | AQ21: =IF($E21=AQ$8,1,0) -> 0 | AR21: =IF($J21=AQ$8,1,0) -> 0 | AS21: =IF($E21=AS$8,1,0) -> 0 | AT21: =IF($J21=AS$8,1,0) -> 0 | AU21: =IF($E21=AU$8,1,0) -> 0 | AV21: =IF($J21=AU$8,1,0) -> 0 | AW21: =IF($E21=AW$8,1,0) -> 0 | AX21: =IF($J21=AW$8,1,0) -> 0 | AY21: =IF($E21=AY$8,1,0) -> 0 | AZ21: =IF($J21=AY$8,1,0) -> 0 | BA21: =IF($E21=BA$8,1,0) -> 0 | BB21: =IF($J21=BA$8,1,0) -> 0 | BC21: =IF($E21=BC$8,1,0) -> 0 | BD21: =IF($J21=BC$8,1,0) -> 0 | BE21: =IF($E21=BE$8,1,0) -> 0 | BF21: =IF($J21=BE$8,1,0) -> 0 | BG21: =IF($E21=BG$8,1,0) -> 0 | BH21: =IF($J21=BG$8,1,0) -> 0 | BI21: =IF($E21=BI$8,1,0) -> 0 | BJ21: =IF($J21=BI$8,1,0) -> 0 | BK21: =IF($E21=BK$8,1,0) -> 0 | BL21: =IF($J21=BK$8,1,0) -> 0 | BM21: =IF($E21=BM$8,1,0) -> 0 | BN21: =IF($J21=BM$8,1,0) -> 0 | BO21: =IF($E21=BO$8,1,0) -> 0 | BP21: =IF($J21=BO$8,1,0) -> 0 | BQ21: =IF($E21=BQ$8,1,0) -> 0 | BR21: =IF($J21=BQ$8,1,0) -> 0 | BS21: =IF($E21=BS$8,1,0) -> 0 | BT21: =IF($J21=BS$8,1,0) -> 0 | BU21: =IF($E21=BU$8,1,0) -> 0 | BV21: =IF($J21=BU$8,1,0) -> 0 | BW21: =IF($E21=BW$8,1,0) -> 0 | BX21: =IF($J21=BW$8,1,0) -> 0 | BY21: =IF($E21=BY$8,1,0) -> 0 | BZ21: =IF($J21=BY$8,1,0) -> 0 | CA21: =IF($E21=CA$8,1,0) -> 0 | CB21: =IF($J21=CA$8,1,0) -> 0 | CC21: =IF($E21=CC$8,1,0) -> 0 | CD21: =IF($J21=CC$8,1,0) -> 0 | CE21: =IF($E21=CE$8,1,0) -> 0 | CF21: =IF($J21=CE$8,1,0) -> 0 | CG21: =IF($E21=CG$8,1,0) -> 0 | CH21: =IF($J21=CG$8,1,0) -> 0 | CI21: =IF($E21=CI$8,1,0) -> 0 | CJ21: =IF($J21=CI$8,1,0) -> 0 | CK21: =IF($E21=CK$8,1,0) -> 0 | CL21: =IF($J21=CK$8,1,0) -> 0 | CM21: =IF($E21=CM$8,1,0) -> 0 | CN21: =IF($J21=CM$8,1,0) -> 0 | CO21: =IF($E21=CO$8,1,0) -> 0 | CP21: =IF($J21=CO$8,1,0) -> 0 | CQ21: =IF($E21=CQ$8,1,0) -> 0 | CR21: =IF($J21=CQ$8,1,0) -> 0 | CS21: =(SUM(Q21:CL21))+(SUM(Q21:CR21)) -> 4 | CT21: =IFERROR((VLOOKUP(A21,'Quad-Tech'!$F$1:$G$17,2,FALSE)),0) -> 0
... A36: =A35+1 -> 45013 | D36: =VLOOKUP(A36,'Quad-Tech'!A29:B393,2,FALSE) -> Tue | E36: 焚化爐（MVAC & ELV） | J36: 焚化爐（MVAC & ELV） | Q36: =IF($E36=Q$8,1,0) -> 0 | R36: =IF($J36=Q$8,1,0) -> 0 | S36: =IF($E36=S$8,1,0) -> 0 | T36: =IF($J36=S$8,1,0) -> 0 | U36: =IF($E36=U$8,1,0) -> 0 | V36: =IF($J36=U$8,1,0) -> 0 | W36: =IF($E36=W$8,1,0) -> 0 | X36: =IF($J36=W$8,1,0) -> 0 | Y36: =IF($E36=Y$8,1,0) -> 0 | Z36: =IF($J36=Y$8,1,0) -> 0 | AA36: =IF($E36=AA$8,1,0) -> 0 | AB36: =IF($J36=AA$8,1,0) -> 0 | AC36: =IF($E36=AC$8,1,0) -> 0 | AD36: =IF($J36=AC$8,1,0) -> 0 | AE36: =IF($E36=AE$8,1,0) -> 0 | AF36: =IF($J36=AE$8,1,0) -> 0 | AG36: =IF($E36=AG$8,1,0) -> 0 | AH36: =IF($J36=AG$8,1,0) -> 0 | AI36: =IF($E36=AI$8,1,0) -> 0 | AJ36: =IF($J36=AI$8,1,0) -> 0 | AK36: =IF($E36=AK$8,1,0) -> 0 | AL36: =IF($J36=AK$8,1,0) -> 0 | AM36: =IF($E36=AM$8,1,0) -> 0 | AN36: =IF($J36=AM$8,1,0) -> 0 | AO36: =IF($E36=AO$8,1,0) -> 0 | AP36: =IF($J36=AO$8,1,0) -> 0 | AQ36: =IF($E36=AQ$8,1,0) -> 0 | AR36: =IF($J36=AQ$8,1,0) -> 0 | AS36: =IF($E36=AS$8,1,0) -> 0 | AT36: =IF($J36=AS$8,1,0) -> 0 | AU36: =IF($E36=AU$8,1,0) -> 0 | AV36: =IF($J36=AU$8,1,0) -> 0 | AW36: =IF($E36=AW$8,1,0) -> 0 | AX36: =IF($J36=AW$8,1,0) -> 0 | AY36: =IF($E36=AY$8,1,0) -> 0 | AZ36: =IF($J36=AY$8,1,0) -> 0 | BA36: =IF($E36=BA$8,1,0) -> 1 | BB36: =IF($J36=BA$8,1,0) -> 1 | BC36: =IF($E36=BC$8,1,0) -> 0 | BD36: =IF($J36=BC$8,1,0) -> 0 | BE36: =IF($E36=BE$8,1,0) -> 0 | BF36: =IF($J36=BE$8,1,0) -> 0 | BG36: =IF($E36=BG$8,1,0) -> 0 | BH36: =IF($J36=BG$8,1,0) -> 0 | BI36: =IF($E36=BI$8,1,0) -> 0 | BJ36: =IF($J36=BI$8,1,0) -> 0 | BK36: =IF($E36=BK$8,1,0) -> 0 | BL36: =IF($J36=BK$8,1,0) -> 0 | BM36: =IF($E36=BM$8,1,0) -> 0 | BN36: =IF($J36=BM$8,1,0) -> 0 | BO36: =IF($E36=BO$8,1,0) -> 0 | BP36: =IF($J36=BO$8,1,0) -> 0 | BQ36: =IF($E36=BQ$8,1,0) -> 0 | BR36: =IF($J36=BQ$8,1,0) -> 0 | BS36: =IF($E36=BS$8,1,0) -> 0 | BT36: =IF($J36=BS$8,1,0) -> 0 | BU36: =IF($E36=BU$8,1,0) -> 0 | BV36: =IF($J36=BU$8,1,0) -> 0 | BW36: =IF($E36=BW$8,1,0) -> 0 | BX36: =IF($J36=BW$8,1,0) -> 0 | BY36: =IF($E36=BY$8,1,0) -> 0 | BZ36: =IF($J36=BY$8,1,0) -> 0 | CA36: =IF($E36=CA$8,1,0) -> 0 | CB36: =IF($J36=CA$8,1,0) -> 0 | CC36: =IF($E36=CC$8,1,0) -> 0 | CD36: =IF($J36=CC$8,1,0) -> 0 | CE36: =IF($E36=CE$8,1,0) -> 0 | CF36: =IF($J36=CE$8,1,0) -> 0 | CG36: =IF($E36=CG$8,1,0) -> 0 | CH36: =IF($J36=CG$8,1,0) -> 0 | CI36: =IF($E36=CI$8,1,0) -> 0 | CJ36: =IF($J36=CI$8,1,0) -> 0 | CK36: =IF($E36=CK$8,1,0) -> 0 | CL36: =IF($J36=CK$8,1,0) -> 0 | CM36: =IF($E36=CM$8,1,0) -> 0 | CN36: =IF($J36=CM$8,1,0) -> 0 | CO36: =IF($E36=CO$8,1,0) -> 0 | CP36: =IF($J36=CO$8,1,0) -> 0 | CQ36: =IF($E36=CQ$8,1,0) -> 0 | CR36: =IF($J36=CQ$8,1,0) -> 0 | CS36: =(SUM(Q36:CL36))+(SUM(Q36:CR36)) -> 4 | CT36: =IFERROR((VLOOKUP(A36,'Quad-Tech'!$F$1:$G$17,2,FALSE)),0) -> 0
A37: =IF(N3="Feb","",A36+1) -> 45014 | D37: =IFERROR((VLOOKUP(A37,'Quad-Tech'!A30:B394,2,FALSE)),"") -> Wed | E37: 焚化爐（MVAC & ELV） | J37: 焚化爐（MVAC & ELV） | Q37: =IF($E37=Q$8,1,0) -> 0 | R37: =IF($J37=Q$8,1,0) -> 0 | S37: =IF($E37=S$8,1,0) -> 0 | T37: =IF($J37=S$8,1,0) -> 0 | U37: =IF($E37=U$8,1,0) -> 0 | V37: =IF($J37=U$8,1,0) -> 0 | W37: =IF($E37=W$8,1,0) -> 0 | X37: =IF($J37=W$8,1,0) -> 0 | Y37: =IF($E37=Y$8,1,0) -> 0 | Z37: =IF($J37=Y$8,1,0) -> 0 | AA37: =IF($E37=AA$8,1,0) -> 0 | AB37: =IF($J37=AA$8,1,0) -> 0 | AC37: =IF($E37=AC$8,1,0) -> 0 | AD37: =IF($J37=AC$8,1,0) -> 0 | AE37: =IF($E37=AE$8,1,0) -> 0 | AF37: =IF($J37=AE$8,1,0) -> 0 | AG37: =IF($E37=AG$8,1,0) -> 0 | AH37: =IF($J37=AG$8,1,0) -> 0 | AI37: =IF($E37=AI$8,1,0) -> 0 | AJ37: =IF($J37=AI$8,1,0) -> 0 | AK37: =IF($E37=AK$8,1,0) -> 0 | AL37: =IF($J37=AK$8,1,0) -> 0 | AM37: =IF($E37=AM$8,1,0) -> 0 | AN37: =IF($J37=AM$8,1,0) -> 0 | AO37: =IF($E37=AO$8,1,0) -> 0 | AP37: =IF($J37=AO$8,1,0) -> 0 | AQ37: =IF($E37=AQ$8,1,0) -> 0 | AR37: =IF($J37=AQ$8,1,0) -> 0 | AS37: =IF($E37=AS$8,1,0) -> 0 | AT37: =IF($J37=AS$8,1,0) -> 0 | AU37: =IF($E37=AU$8,1,0) -> 0 | AV37: =IF($J37=AU$8,1,0) -> 0 | AW37: =IF($E37=AW$8,1,0) -> 0 | AX37: =IF($J37=AW$8,1,0) -> 0 | AY37: =IF($E37=AY$8,1,0) -> 0 | AZ37: =IF($J37=AY$8,1,0) -> 0 | BA37: =IF($E37=BA$8,1,0) -> 1 | BB37: =IF($J37=BA$8,1,0) -> 1 | BC37: =IF($E37=BC$8,1,0) -> 0 | BD37: =IF($J37=BC$8,1,0) -> 0 | BE37: =IF($E37=BE$8,1,0) -> 0 | BF37: =IF($J37=BE$8,1,0) -> 0 | BG37: =IF($E37=BG$8,1,0) -> 0 | BH37: =IF($J37=BG$8,1,0) -> 0 | BI37: =IF($E37=BI$8,1,0) -> 0 | BJ37: =IF($J37=BI$8,1,0) -> 0 | BK37: =IF($E37=BK$8,1,0) -> 0 | BL37: =IF($J37=BK$8,1,0) -> 0 | BM37: =IF($E37=BM$8,1,0) -> 0 | BN37: =IF($J37=BM$8,1,0) -> 0 | BO37: =IF($E37=BO$8,1,0) -> 0 | BP37: =IF($J37=BO$8,1,0) -> 0 | BQ37: =IF($E37=BQ$8,1,0) -> 0 | BR37: =IF($J37=BQ$8,1,0) -> 0 | BS37: =IF($E37=BS$8,1,0) -> 0 | BT37: =IF($J37=BS$8,1,0) -> 0 | BU37: =IF($E37=BU$8,1,0) -> 0 | BV37: =IF($J37=BU$8,1,0) -> 0 | BW37: =IF($E37=BW$8,1,0) -> 0 | BX37: =IF($J37=BW$8,1,0) -> 0 | BY37: =IF($E37=BY$8,1,0) -> 0 | BZ37: =IF($J37=BY$8,1,0) -> 0 | CA37: =IF($E37=CA$8,1,0) -> 0 | CB37: =IF($J37=CA$8,1,0) -> 0 | CC37: =IF($E37=CC$8,1,0) -> 0 | CD37: =IF($J37=CC$8,1,0) -> 0 | CE37: =IF($E37=CE$8,1,0) -> 0 | CF37: =IF($J37=CE$8,1,0) -> 0 | CG37: =IF($E37=CG$8,1,0) -> 0 | CH37: =IF($J37=CG$8,1,0) -> 0 | CI37: =IF($E37=CI$8,1,0) -> 0 | CJ37: =IF($J37=CI$8,1,0) -> 0 | CK37: =IF($E37=CK$8,1,0) -> 0 | CL37: =IF($J37=CK$8,1,0) -> 0 | CM37: =IF($E37=CM$8,1,0) -> 0 | CN37: =IF($J37=CM$8,1,0) -> 0 | CO37: =IF($E37=CO$8,1,0) -> 0 | CP37: =IF($J37=CO$8,1,0) -> 0 | CQ37: =IF($E37=CQ$8,1,0) -> 0 | CR37: =IF($J37=CQ$8,1,0) -> 0 | CS37: =(SUM(Q37:CL37))+(SUM(Q37:CR37)) -> 4 | CT37: =IFERROR((VLOOKUP(A37,'Quad-Tech'!$F$1:$G$17,2,FALSE)),0) -> 0
A38: =IF(N3="Feb","",A37+1) -> 45015 | D38: =IFERROR((VLOOKUP(A38,'Quad-Tech'!A31:B395,2,FALSE)),"") -> Thu | E38: 焚化爐（MVAC & ELV） | J38: 焚化爐（MVAC & ELV） | Q38: =IF($E38=Q$8,1,0) -> 0 | R38: =IF($J38=Q$8,1,0) -> 0 | S38: =IF($E38=S$8,1,0) -> 0 | T38: =IF($J38=S$8,1,0) -> 0 | U38: =IF($E38=U$8,1,0) -> 0 | V38: =IF($J38=U$8,1,0) -> 0 | W38: =IF($E38=W$8,1,0) -> 0 | X38: =IF($J38=W$8,1,0) -> 0 | Y38: =IF($E38=Y$8,1,0) -> 0 | Z38: =IF($J38=Y$8,1,0) -> 0 | AA38: =IF($E38=AA$8,1,0) -> 0 | AB38: =IF($J38=AA$8,1,0) -> 0 | AC38: =IF($E38=AC$8,1,0) -> 0 | AD38: =IF($J38=AC$8,1,0) -> 0 | AE38: =IF($E38=AE$8,1,0) -> 0 | AF38: =IF($J38=AE$8,1,0) -> 0 | AG38: =IF($E38=AG$8,1,0) -> 0 | AH38: =IF($J38=AG$8,1,0) -> 0 | AI38: =IF($E38=AI$8,1,0) -> 0 | AJ38: =IF($J38=AI$8,1,0) -> 0 | AK38: =IF($E38=AK$8,1,0) -> 0 | AL38: =IF($J38=AK$8,1,0) -> 0 | AM38: =IF($E38=AM$8,1,0) -> 0 | AN38: =IF($J38=AM$8,1,0) -> 0 | AO38: =IF($E38=AO$8,1,0) -> 0 | AP38: =IF($J38=AO$8,1,0) -> 0 | AQ38: =IF($E38=AQ$8,1,0) -> 0 | AR38: =IF($J38=AQ$8,1,0) -> 0 | AS38: =IF($E38=AS$8,1,0) -> 0 | AT38: =IF($J38=AS$8,1,0) -> 0 | AU38: =IF($E38=AU$8,1,0) -> 0 | AV38: =IF($J38=AU$8,1,0) -> 0 | AW38: =IF($E38=AW$8,1,0) -> 0 | AX38: =IF($J38=AW$8,1,0) -> 0 | AY38: =IF($E38=AY$8,1,0) -> 0 | AZ38: =IF($J38=AY$8,1,0) -> 0 | BA38: =IF($E38=BA$8,1,0) -> 1 | BB38: =IF($J38=BA$8,1,0) -> 1 | BC38: =IF($E38=BC$8,1,0) -> 0 | BD38: =IF($J38=BC$8,1,0) -> 0 | BE38: =IF($E38=BE$8,1,0) -> 0 | BF38: =IF($J38=BE$8,1,0) -> 0 | BG38: =IF($E38=BG$8,1,0) -> 0 | BH38: =IF($J38=BG$8,1,0) -> 0 | BI38: =IF($E38=BI$8,1,0) -> 0 | BJ38: =IF($J38=BI$8,1,0) -> 0 | BK38: =IF($E38=BK$8,1,0) -> 0 | BL38: =IF($J38=BK$8,1,0) -> 0 | BM38: =IF($E38=BM$8,1,0) -> 0 | BN38: =IF($J38=BM$8,1,0) -> 0 | BO38: =IF($E38=BO$8,1,0) -> 0 | BP38: =IF($J38=BO$8,1,0) -> 0 | BQ38: =IF($E38=BQ$8,1,0) -> 0 | BR38: =IF($J38=BQ$8,1,0) -> 0 | BS38: =IF($E38=BS$8,1,0) -> 0 | BT38: =IF($J38=BS$8,1,0) -> 0 | BU38: =IF($E38=BU$8,1,0) -> 0 | BV38: =IF($J38=BU$8,1,0) -> 0 | BW38: =IF($E38=BW$8,1,0) -> 0 | BX38: =IF($J38=BW$8,1,0) -> 0 | BY38: =IF($E38=BY$8,1,0) -> 0 | BZ38: =IF($J38=BY$8,1,0) -> 0 | CA38: =IF($E38=CA$8,1,0) -> 0 | CB38: =IF($J38=CA$8,1,0) -> 0 | CC38: =IF($E38=CC$8,1,0) -> 0 | CD38: =IF($J38=CC$8,1,0) -> 0 | CE38: =IF($E38=CE$8,1,0) -> 0 | CF38: =IF($J38=CE$8,1,0) -> 0 | CG38: =IF($E38=CG$8,1,0) -> 0 | CH38: =IF($J38=CG$8,1,0) -> 0 | CI38: =IF($E38=CI$8,1,0) -> 0 | CJ38: =IF($J38=CI$8,1,0) -> 0 | CK38: =IF($E38=CK$8,1,0) -> 0 | CL38: =IF($J38=CK$8,1,0) -> 0 | CM38: =IF($E38=CM$8,1,0) -> 0 | CN38: =IF($J38=CM$8,1,0) -> 0 | CO38: =IF($E38=CO$8,1,0) -> 0 | CP38: =IF($J38=CO$8,1,0) -> 0 | CQ38: =IF($E38=CQ$8,1,0) -> 0 | CR38: =IF($J38=CQ$8,1,0) -> 0 | CS38: =(SUM(Q38:CL38))+(SUM(Q38:CR38)) -> 4 | CT38: =IFERROR((VLOOKUP(A38,'Quad-Tech'!$F$1:$G$17,2,FALSE)),0) -> 0
A39: =IF(N3="Feb","",IF(N3="Apr","",IF(N3="Jun","",IF(N3="Sep","",IF(N3="Nov","",A38+1))))) -> 45016 | D39: =IFERROR((VLOOKUP(A39,'Quad-Tech'!A32:B396,2,FALSE)),"") -> Fri | E39: 焚化爐（MVAC & ELV） | J39: 焚化爐（MVAC & ELV） | Q39: =IF($E39=Q$8,1,0) -> 0 | R39: =IF($J39=Q$8,1,0) -> 0 | S39: =IF($E39=S$8,1,0) -> 0 | T39: =IF($J39=S$8,1,0) -> 0 | U39: =IF($E39=U$8,1,0) -> 0 | V39: =IF($J39=U$8,1,0) -> 0 | W39: =IF($E39=W$8,1,0) -> 0 | X39: =IF($J39=W$8,1,0) -> 0 | Y39: =IF($E39=Y$8,1,0) -> 0 | Z39: =IF($J39=Y$8,1,0) -> 0 | AA39: =IF($E39=AA$8,1,0) -> 0 | AB39: =IF($J39=AA$8,1,0) -> 0 | AC39: =IF($E39=AC$8,1,0) -> 0 | AD39: =IF($J39=AC$8,1,0) -> 0 | AE39: =IF($E39=AE$8,1,0) -> 0 | AF39: =IF($J39=AE$8,1,0) -> 0 | AG39: =IF($E39=AG$8,1,0) -> 0 | AH39: =IF($J39=AG$8,1,0) -> 0 | AI39: =IF($E39=AI$8,1,0) -> 0 | AJ39: =IF($J39=AI$8,1,0) -> 0 | AK39: =IF($E39=AK$8,1,0) -> 0 | AL39: =IF($J39=AK$8,1,0) -> 0 | AM39: =IF($E39=AM$8,1,0) -> 0 | AN39: =IF($J39=AM$8,1,0) -> 0 | AO39: =IF($E39=AO$8,1,0) -> 0 | AP39: =IF($J39=AO$8,1,0) -> 0 | AQ39: =IF($E39=AQ$8,1,0) -> 0 | AR39: =IF($J39=AQ$8,1,0) -> 0 | AS39: =IF($E39=AS$8,1,0) -> 0 | AT39: =IF($J39=AS$8,1,0) -> 0 | AU39: =IF($E39=AU$8,1,0) -> 0 | AV39: =IF($J39=AU$8,1,0) -> 0 | AW39: =IF($E39=AW$8,1,0) -> 0 | AX39: =IF($J39=AW$8,1,0) -> 0 | AY39: =IF($E39=AY$8,1,0) -> 0 | AZ39: =IF($J39=AY$8,1,0) -> 0 | BA39: =IF($E39=BA$8,1,0) -> 1 | BB39: =IF($J39=BA$8,1,0) -> 1 | BC39: =IF($E39=BC$8,1,0) -> 0 | BD39: =IF($J39=BC$8,1,0) -> 0 | BE39: =IF($E39=BE$8,1,0) -> 0 | BF39: =IF($J39=BE$8,1,0) -> 0 | BG39: =IF($E39=BG$8,1,0) -> 0 | BH39: =IF($J39=BG$8,1,0) -> 0 | BI39: =IF($E39=BI$8,1,0) -> 0 | BJ39: =IF($J39=BI$8,1,0) -> 0 | BK39: =IF($E39=BK$8,1,0) -> 0 | BL39: =IF($J39=BK$8,1,0) -> 0 | BM39: =IF($E39=BM$8,1,0) -> 0 | BN39: =IF($J39=BM$8,1,0) -> 0 | BO39: =IF($E39=BO$8,1,0) -> 0 | BP39: =IF($J39=BO$8,1,0) -> 0 | BQ39: =IF($E39=BQ$8,1,0) -> 0 | BR39: =IF($J39=BQ$8,1,0) -> 0 | BS39: =IF($E39=BS$8,1,0) -> 0 | BT39: =IF($J39=BS$8,1,0) -> 0 | BU39: =IF($E39=BU$8,1,0) -> 0 | BV39: =IF($J39=BU$8,1,0) -> 0 | BW39: =IF($E39=BW$8,1,0) -> 0 | BX39: =IF($J39=BW$8,1,0) -> 0 | BY39: =IF($E39=BY$8,1,0) -> 0 | BZ39: =IF($J39=BY$8,1,0) -> 0 | CA39: =IF($E39=CA$8,1,0) -> 0 | CB39: =IF($J39=CA$8,1,0) -> 0 | CC39: =IF($E39=CC$8,1,0) -> 0 | CD39: =IF($J39=CC$8,1,0) -> 0 | CE39: =IF($E39=CE$8,1,0) -> 0 | CF39: =IF($J39=CE$8,1,0) -> 0 | CG39: =IF($E39=CG$8,1,0) -> 0 | CH39: =IF($J39=CG$8,1,0) -> 0 | CI39: =IF($E39=CI$8,1,0) -> 0 | CJ39: =IF($J39=CI$8,1,0) -> 0 | CK39: =IF($E39=CK$8,1,0) -> 0 | CL39: =IF($J39=CK$8,1,0) -> 0 | CM39: =IF($E39=CM$8,1,0) -> 0 | CN39: =IF($J39=CM$8,1,0) -> 0 | CO39: =IF($E39=CO$8,1,0) -> 0 | CP39: =IF($J39=CO$8,1,0) -> 0 | CQ39: =IF($E39=CQ$8,1,0) -> 0 | CR39: =IF($J39=CQ$8,1,0) -> 0 | CS39: =(SUM(Q39:CL39))+(SUM(Q39:CR39)) -> 4 | CT39: =IFERROR((VLOOKUP(A39,'Quad-Tech'!$F$1:$G$17,2,FALSE)),0) -> 0
A40: PRO/JOB REF : | Q40: =SUM(Q9:Q39) -> 0 | R40: =SUM(R9:R39) -> 0 | S40: =SUM(S9:S39) -> 4 | T40: =SUM(T9:T39) -> 4 | U40: =SUM(U9:U39) -> 1 | V40: =SUM(V9:V39) -> 1 | W40: =SUM(W9:W39) -> 0 | X40: =SUM(X9:X39) -> 0 | ... CR40: =SUM(CR9:CR39) -> 0 | CS40: =(SUM(Q40:CR40))+(SUM(Q40:CR40)) -> 124
B41: AL | D41: =SUM(W40:X40) -> 0 | E41: 2107EM20M | F41: Eastern Harbour Tunnel | H41: =SUM(AE$40:AF$40) -> 0 | I41: J 210652-C | J41: 元朗宏業西街 | L41: =SUM(AU$40:AV$40) -> 0 | N41: Tendering | Q41: total: | T41: =SUM(T44:T46) -> 51
B42: SL | D42: =SUM(U40:V40) -> 2 | E42: 2656EM20M | F42: Hotung Secondary School | H42: =SUM(AG$40:AH$40) -> 12 | I42: J 220680-C | J42: Kai Tak 1B2 | L42: =SUM(AW$40:AX$40) -> 9 | N42: Kai Tak 1B3 | P42: =SUM(BG$40:BH$40) -> 0
B43: NPL | D43: =SUM(Q40:R40) -> 0 | E43: 3083EM20M | F43: Hong Kong Children's Hospital | H43: =SUM(AI$40:AJ$40) -> 0 | I43: J 230682 | J43: Tsat Sing Kong | L43: =SUM(AY$40:AZ$40) -> 0 | N43: GDS KC1 | P43: =SUM(BI$40:BJ$40) -> 0
B44: PH | D44: =SUM(S40:T40) -> 8 | E44: 2435EM21M | F44: 學校 Project | H44: =SUM(AK$40:AL$40) -> 0 | I44: SC1108 | J44: 焚化爐（MVAC & ELV） | L44: =SUM(BA$40:BB$40) -> 12 | N44: GDS KC2 | P44: =SUM(BK$40:BL$40) -> 0 | Q44: PH+SL+AL | T44: =SUM(S40:X40) -> 10
B45: OFF | D45: =SUM(AA40:AB40) -> 6 | E45: 1497EM22M | F45: Shatin Hospital | H45: =SUM(AM$40:AN$40) -> 0 | N45: EMSD Tender | P45: =SUM(BE$40:BF$40) -> 5 | Q45: OFF | T45: =Q40+R40 -> 0
B46: Admin | D46: =SUM(AC40:AD40) -> 0 | E46: 1611EM22M | F46: North Lantau Hospital | H46: =SUM(AO$40:AP$40) -> 0 | N46: General Tendering | P46: =SUM(BC$40:BD$40) -> 2 | Q46: working | T46: =SUM(AE40:BD40) -> 41
B47: CL | D47: =SUM(Y40:Z40) -> 0 | E47: 1865EM22M | F47: 學校 Project | H47: =SUM(AQ$40:AR$40) -> 0
E48: 1735EM22W | F48: New Territories West | H48: =SUM(AS$40:AT$40) -> 6
N49: Total: | O49: =SUM(D41:D49,H41:H49,L41:L49,M41:M49,P41:P48) -> 62
A50: ADMIN. / ACCOUNT : | F50: CHECKED BY : | L50: APPROVED BY :
L52: (Ben Liu - Director)
A54: 09:00-12:00 / 13:30-18:00 - 半天為 1 單位

Sheet Quad-Tech
A1: Jan | C1: Month | E1: The day following the first day of January | F1: 44928 | G1: Mon
A2: 44927 | B2: Sun | C2: Jan | E2: The second day of Lunar New Year | F2: 44949 | G2: Mon
A3: 44928 | B3: Mon | C3: Feb | E3: The third day of Lunar New Year | F3: 44950 | G3: Tue
A4: 44929 | B4: Tue | C4: Mar | E4: The fourth day of Lunar New Year | F4: 44951 | G4: Wed
A5: 44930 | B5: Wed | C5: Apr | E5: Ching Ming Festival | F5: 45021 | G5: Wed
A6: 44931 | B6: Thu | C6: May | E6: Good Friday | F6: 45023 | G6: Fri
A7: 44932 | B7: Fri | C7: Jun | E7: The day following Good Friday | F7: 45024 | G7: Sat
A8: 44933 | B8: Sat | C8: Jul | E8: Easter Monday | F8: 45026 | G8: Mon
A9: 44934 | B9: Sun | C9: Aug | E9: Labour Day | F9: 45047 | G9: Mon
A10: 44935 | B10: Mon | C10: Sep | E10: Birthday of the Buddha | F10: 45072 | G10: Fri
A11: 44936 | B11: Tue | C11: Oct | E11: Tuen Ng Festival | F11: 45099 | G11: Thu
A12: 44937 | B12: Wed | C12: Nov | E12: Hong Kong Special Administrative Region Establishment Day | F12: 45108 | G12: Sat
A13: 44938 | B13: Thu | C13: Dec | E13: The day following the Chinese Mid-Autumn Festival | F13: 45199 | G13: Sat
A14: 44939 | B14: Fri | E14: The day following National Day | F14: 45201 | G14: Mon
A15: 44940 | B15: Sat | E15: Chung Yeung Festival | F15: 45222 | G15: Mon
A16: 44941 | B16: Sun | E16: Christmas Day | F16: 45285 | G16: Mon
A17: 44942 | B17: Mon | E17: The first weekday after Christmas Day | F17: 45286 | G17: Tue
A18: 44943 | B18: Tue
A19: 44944 | B19: Wed
A20: 44945 | B20: Thu
A21: 44946 | B21: Fri
A22: 44947 | B22: Sat | E22: AL
A23: 44948 | B23: Sun | E23: SL
A24: 44949 | B24: Mon | E24: NPL
A25: 44950 | B25: Tue | E25: PH
A26: 44951 | B26: Wed | E26: OFF
A27: 44952 | B27: Thu | E27: Admin
A28: 44953 | B28: Fri | E28: CL
A29: 44954 | B29: Sat | E29: 2107EM20M | F29: Eastern Harbour Tunnel
A30: 44955 | B30: Sun | E30: 2656EM20M | F30: Hotung Secondary School
A31: 44956 | B31: Mon | E31: 3083EM20M | F31: Hong Kong Children's Hospital
A32: 44957 | B32: Tue | E32: 2435EM21M | F32: 學校 Project
A33: 44958 | B33: Wed | E33: 1497EM22M | F33: Shatin Hospital
A34: 44959 | B34: Thu | E34: 1611EM22M | F34: North Lantau Hospital
A35: 44960 | B35: Fri | E35: 1865EM22M | F35: 學校 Project
A36: 44961 | B36: Sat | E36: 1735EM22W | F36: New Territories West
A37: 44962 | B37: Sun | E37: 元朗宏業西街
A38: 44963 | B38: Mon | E38: Kai Tak 1B2
A39: 44964 | B39: Tue | E39: Tsat Sing Kong
A40: 44965 | B40: Wed | E40: 焚化爐（MVAC & ELV）
...

Sheet OLD
A1: 工程編號 | B1: 工程地盤
A2: AL
A3: SL
A4: NPL
A5: 補假
A6: PH
A7: Tender
A8: Admin
A9: PRO023 | B9: CMC2
A10: PRO028 | B10: SSY302 YLL
A11: PRO032 | B11: HKJC Hospice
A12: PRO038 | B12: SSY302 YLL
A13: PRO046 | B13: THEi (VTC)
A14: PRO048 | B14: TKT BEAM Plus
A15: PRO052 | B15: HHR
A16: PRO053 | B16: RRH
A17: PRO054 | B17: RKH
A18: PRO055 | B18: Towngas
A19: PRO056 | B19: Shek Mun
A20: PRO057 | B20: Lok Wo Sha
... A35: PRO17-013 | B35: 華潤大廈
